Workbook

Sheet Làm nhanh
A2: Làm một khối rồi dừng
A4: 1. Mở đề. 2. Ghi lựa chọn. 3. Chọn Xong. 4. Ghi ngày/phút/loại câu.
A5: Vàng để nhập. 0 = bỏ câu; trống = chưa làm. Không mở khóa khi đang đo.
A6: Mỗi khối chọn một chế độ. Đã có lịch sử thì giữ nguyên, không ghi đè lần đầu.
A7: N4-G1 | B7: N4-G2 | C7: N4-V | D7: N4-R | E7: N4-L1 | F7: N4-L2
A8: N3-G | B8: N3-V | C8: N3-R | D8: N3-L1 | E8: N3-L2
A10: N4-G1 · Ngữ pháp · 6 phút làm
A11: Nguồn JLPT | B11: Mở đề | E11: Khóa sau khi làm
A12: Câu | B12: 1 | C12: 2 | D12: 3 | E12: 4 | F12: 5 | G12: 6
A13: Bạn chọn
A16: Ngày thật | C16: Phút làm | E16: Loại câu | I16: =IF(ISBLANK(B13),0,IF(ISNUMBER(B13),IF(AND(B13>=0,B13<=4,MOD(B13,1)=0),1,-1),-1)) -> 0 | J16: =IF(I16=1,IF(B13='Chẩn đoán'!N8,1,0),0) -> 0
A17: Chấm sau giờ | D17: Dở dang: để nguyên; chưa chọn Xong. | I17: =IF(ISBLANK(C13),0,IF(ISNUMBER(C13),IF(AND(C13>=0,C13<=4,MOD(C13,1)=0),1,-1),-1)) -> 0 | J17: =IF(I17=1,IF(C13='Chẩn đoán'!N9,1,0),0) -> 0
A18: Trạng thái | B18: =P172 -> Chưa làm | I18: =IF(ISBLANK(D13),0,IF(ISNUMBER(D13),IF(AND(D13>=0,D13<=4,MOD(D13,1)=0),1,-1),-1)) -> 0 | J18: =IF(I18=1,IF(D13='Chẩn đoán'!N10,1,0),0) -> 0
A19: Kết quả | B19: =IF(AND(B17="Xong",R172=K172,S172=0),T172&"/"&K172&" đúng; 0 vẫn tính bỏ câu","Đã ghi "&R172&"/"&K172&"; chưa hiện điểm") -> Đã ghi 0/6; chưa hiện điểm | I19: =IF(ISBLANK(E13),0,IF(ISNUMBER(E13),IF(AND(E13>=0,E13<=4,MOD(E13,1)=0),1,-1),-1)) -> 0 | J19: =IF(I19=1,IF(E13='Chẩn đoán'!N11,1,0),0) -> 0
A20: Câu cần sửa | B20: =IF(AND(B17="Xong",R172=K172,S172=0),IF(X172="","Không có câu sai/bỏ",X172),"Chỉ hiện sau khi làm xong") -> Chỉ hiện sau khi làm xong | I20: =IF(ISBLANK(F13),0,IF(ISNUMBER(F13),IF(AND(F13>=0,F13<=4,MOD(F13,1)=0),1,-1),-1)) -> 0 | J20: =IF(I20=1,IF(F13='Chẩn đoán'!N12,1,0),0) -> 0
A21: Lỗi chính | E21: Xem tuần | I21: =IF(ISBLANK(G13),0,IF(ISNUMBER(G13),IF(AND(G13>=0,G13<=4,MOD(G13,1)=0),1,-1),-1)) -> 0 | J21: =IF(I21=1,IF(G13='Chẩn đoán'!N13,1,0),0) -> 0
A22: Tiếp theo | B22: =IF(P172="Đã chấm","Chọn 1 lỗi để chữa 5-10 phút rồi dừng.",IF(P172="Trùng hai chế độ","Giữ lịch sử ở Chẩn đoán; xóa bản nhập trùng ở đây.","Hoàn tất khi đủ sức; không ép làm khối tiếp.")) -> Hoàn tất khi đủ sức; không ép làm khối tiếp. | I22: =IF(ISBLANK(B27),0,IF(ISNUMBER(B27),IF(AND(B27>=0,B27<=4,MOD(B27,1)=0),1,-1),-1)) -> 0 | J22: =IF(I22=1,IF(B27='Chẩn đoán'!N14,1,0),0) -> 0
I23: =IF(ISBLANK(C27),0,IF(ISNUMBER(C27),IF(AND(C27>=0,C27<=4,MOD(C27,1)=0),1,-1),-1)) -> 0 | J23: =IF(I23=1,IF(C27='Chẩn đoán'!N15,1,0),0) -> 0
A24: N4-G2 · Ngữ pháp · 6 phút làm | I24: =IF(ISBLANK(D27),0,IF(ISNUMBER(D27),IF(AND(D27>=0,D27<=4,MOD(D27,1)=0),1,-1),-1)) -> 0 | J24: =IF(I24=1,IF(D27='Chẩn đoán'!N16,1,0),0) -> 0
A25: Nguồn JLPT | B25: Mở đề | E25: Khóa sau khi làm | I25: =IF(ISBLANK(E27),0,IF(ISNUMBER(E27),IF(AND(E27>=0,E27<=4,MOD(E27,1)=0),1,-1),-1)) -> 0 | J25: =IF(I25=1,IF(E27='Chẩn đoán'!N17,1,0),0) -> 0
A26: Câu | B26: 16 | C26: 17 | D26: 21 | E26: 22 | F26: 23 | G26: 24 | I26: =IF(ISBLANK(F27),0,IF(ISNUMBER(F27),IF(AND(F27>=0,F27<=4,MOD(F27,1)=0),1,-1),-1)) -> 0 | J26: =IF(I26=1,IF(F27='Chẩn đoán'!N18,1,0),0) -> 0
A27: Bạn chọn | I27: =IF(ISBLANK(G27),0,IF(ISNUMBER(G27),IF(AND(G27>=0,G27<=4,MOD(G27,1)=0),1,-1),-1)) -> 0 | J27: =IF(I27=1,IF(G27='Chẩn đoán'!N19,1,0),0) -> 0
A28: Câu tiếp | B28: 25 | I28: =IF(ISBLANK(B29),0,IF(ISNUMBER(B29),IF(AND(B29>=0,B29<=4,MOD(B29,1)=0),1,-1),-1)) -> 0 | J28: =IF(I28=1,IF(B29='Chẩn đoán'!N20,1,0),0) -> 0
A29: Bạn chọn | I29: =IF(ISBLANK(B41),0,IF(ISNUMBER(B41),IF(AND(B41>=0,B41<=4,MOD(B41,1)=0),1,-1),-1)) -> 0 | J29: =IF(I29=1,IF(B41='Chẩn đoán'!N21,1,0),0) -> 0
A30: Ngày thật | C30: Phút làm | E30: Loại câu | I30: =IF(ISBLANK(C41),0,IF(ISNUMBER(C41),IF(AND(C41>=0,C41<=4,MOD(C41,1)=0),1,-1),-1)) -> 0 | J30: =IF(I30=1,IF(C41='Chẩn đoán'!N22,1,0),0) -> 0
A31: Chấm sau giờ | D31: Dở dang: để nguyên; chưa chọn Xong. | I31: =IF(ISBLANK(D41),0,IF(ISNUMBER(D41),IF(AND(D41>=0,D41<=4,MOD(D41,1)=0),1,-1),-1)) -> 0 | J31: =IF(I31=1,IF(D41='Chẩn đoán'!N23,1,0),0) -> 0
A32: Trạng thái | B32: =P173 -> Chưa làm | I32: =IF(ISBLANK(E41),0,IF(ISNUMBER(E41),IF(AND(E41>=0,E41<=4,MOD(E41,1)=0),1,-1),-1)) -> 0 | J32: =IF(I32=1,IF(E41='Chẩn đoán'!N24,1,0),0) -> 0
A33: Kết quả | B33: =IF(AND(B31="Xong",R173=K173,S173=0),T173&"/"&K173&" đúng; 0 vẫn tính bỏ câu","Đã ghi "&R173&"/"&K173&"; chưa hiện điểm") -> Đã ghi 0/7; chưa hiện điểm | I33: =IF(ISBLANK(F41),0,IF(ISNUMBER(F41),IF(AND(F41>=0,F41<=4,MOD(F41,1)=0),1,-1),-1)) -> 0 | J33: =IF(I33=1,IF(F41='Chẩn đoán'!N25,1,0),0) -> 0
A34: Câu cần sửa | B34: =IF(AND(B31="Xong",R173=K173,S173=0),IF(X173="","Không có câu sai/bỏ",X173),"Chỉ hiện sau khi làm xong") -> Chỉ hiện sau khi làm xong | I34: =IF(ISBLANK(G41),0,IF(ISNUMBER(G41),IF(AND(G41>=0,G41<=4,MOD(G41,1)=0),1,-1),-1)) -> 0 | J34: =IF(I34=1,IF(G41='Chẩn đoán'!N26,1,0),0) -> 0
A35: Lỗi chính | E35: Xem tuần | I35: =IF(ISBLANK(B43),0,IF(ISNUMBER(B43),IF(AND(B43>=0,B43<=4,MOD(B43,1)=0),1,-1),-1)) -> 0 | J35: =IF(I35=1,IF(B43='Chẩn đoán'!N27,1,0),0) -> 0
A36: Tiếp theo | B36: =IF(P173="Đã chấm","Chọn 1 lỗi để chữa 5-10 phút rồi dừng.",IF(P173="Trùng hai chế độ","Giữ lịch sử ở Chẩn đoán; xóa bản nhập trùng ở đây.","Hoàn tất khi đủ sức; không ép làm khối tiếp.")) -> Hoàn tất khi đủ sức; không ép làm khối tiếp. | I36: =IF(ISBLANK(C43),0,IF(ISNUMBER(C43),IF(AND(C43>=0,C43<=4,MOD(C43,1)=0),1,-1),-1)) -> 0 | J36: =IF(I36=1,IF(C43='Chẩn đoán'!N28,1,0),0) -> 0
I37: =IF(ISBLANK(D43),0,IF(ISNUMBER(D43),IF(AND(D43>=0,D43<=4,MOD(D43,1)=0),1,-1),-1)) -> 0 | J37: =IF(I37=1,IF(D43='Chẩn đoán'!N29,1,0),0) -> 0
A38: N4-V · Từ và kanji · 8 phút làm | I38: =IF(ISBLANK(E43),0,IF(ISNUMBER(E43),IF(AND(E43>=0,E43<=4,MOD(E43,1)=0),1,-1),-1)) -> 0 | J38: =IF(I38=1,IF(E43='Chẩn đoán'!N30,1,0),0) -> 0
A39: Nguồn JLPT | B39: Mở đề | E39: Khóa sau khi làm | I39: =IF(ISBLANK(B55),0,IF(ISNUMBER(B55),IF(AND(B55>=0,B55<=4,MOD(B55,1)=0),1,-1),-1)) -> 0 | J39: =IF(I39=1,IF(B55='Chẩn đoán'!N31,1,0),0) -> 0
A40: Câu | B40: 1 | C40: 2 | D40: 10 | E40: 11 | F40: 16 | G40: 17 | I40: =IF(ISBLANK(C55),0,IF(ISNUMBER(C55),IF(AND(C55>=0,C55<=4,MOD(C55,1)=0),1,-1),-1)) -> 0 | J40: =IF(I40=1,IF(C55='Chẩn đoán'!N32,1,0),0) -> 0
A41: Bạn chọn | I41: =IF(ISBLANK(D55),0,IF(ISNUMBER(D55),IF(AND(D55>=0,D55<=4,MOD(D55,1)=0),1,-1),-1)) -> 0 | J41: =IF(I41=1,IF(D55='Chẩn đoán'!N33,1,0),0) -> 0
A42: Câu tiếp | B42: 26 | C42: 27 | D42: 31 | E42: 32 | I42: =IF(ISBLANK(E55),0,IF(ISNUMBER(E55),IF(AND(E55>=0,E55<=4,MOD(E55,1)=0),1,-1),-1)) -> 0 | J42: =IF(I42=1,IF(E55='Chẩn đoán'!N34,1,0),0) -> 0
A43: Bạn chọn | I43: =IF(ISBLANK(F55),0,IF(ISNUMBER(F55),IF(AND(F55>=0,F55<=4,MOD(F55,1)=0),1,-1),-1)) -> 0 | J43: =IF(I43=1,IF(F55='Chẩn đoán'!N35,1,0),0) -> 0
A44: Ngày thật | C44: Phút làm | E44: Loại câu | I44: =IF(ISBLANK(B69),0,IF(ISNUMBER(B69),IF(AND(B69>=0,B69<=4,MOD(B69,1)=0),1,-1),-1)) -> 0 | J44: =IF(I44=1,IF(B69='Chẩn đoán'!N36,1,0),0) -> 0
A45: Chấm sau giờ | D45: Dở dang: để nguyên; chưa chọn Xong. | I45: =IF(ISBLANK(C69),0,IF(ISNUMBER(C69),IF(AND(C69>=0,C69<=4,MOD(C69,1)=0),1,-1),-1)) -> 0 | J45: =IF(I45=1,IF(C69='Chẩn đoán'!N37,1,0),0) -> 0
...

Sheet Nhật ký
A2: Nhật ký tiếng Nhật từ 15 tháng 10 đến 5 tháng 12 năm 2026
A4: Ngày có ghi | B4: =COUNT(E8:E59) -> 0 | C4: Phút học | D4: =IF(COUNT(E8:E59)=0,"",SUM(E8:E59)) | E4: Phút nghe | F4: =IF(COUNT(F8:F59)=0,"",SUM(F8:F59)) | G4: Phút nói | H4: =IF(COUNT(G8:G59)=0,"",SUM(G8:G59))
A5: Ô vàng để nhập. Chưa biết để trống; nghỉ thật nhập 0 phút. Ngủ là tổng 24 giờ, gồm ngủ bù.
A6: Nhập chế độ và tổng phút; thêm nghe/nói nếu biết. Mã lỗi ở I. Cột J trở đi tự kiểm tra.
A7: Ngày | B7: Ngủ 24h (giờ) | C7: Mệt 1 đến 5 | D7: Chế độ | E7: Học (phút) | F7: Nghe (phút) | G7: Nói (phút) | H7: Một lỗi hoặc việc tiếp theo | I7: Mã lỗi chính | J7: Kiểm tra dòng | K7: Có giờ ngủ | L7: Có mức mệt | M7: Có phút nghe | N7: Có phút nói | O7: Đã ghi phút học
A8: 46310 | J8: =IF(AND(COUNTA(B8:I8)=0),"",IF(OR(AND(NOT(ISBLANK(B8)),OR(NOT(ISNUMBER(B8)),B8<0,B8>24)),AND(NOT(ISBLANK(C8)),IF(ISNUMBER(C8),OR(C8<1,C8>5,MOD(C8,1)<>0),TRUE))),"Lỗi ngủ/mệt",IF(NOT(ISNUMBER(E8)),"Thiếu tổng phút",IF(OR(E8<0,OR(AND(NOT(ISBLANK(F8)),OR(NOT(ISNUMBER(F8)),F8<0)),AND(NOT(ISBLANK(G8)),OR(NOT(ISNUMBER(G8)),G8<0)))),"Lỗi phút",IF(SUM(F8:G8)>E8,"Nghe+nói vượt tổng",IF(AND(D8<>"Nghỉ",D8<>"Kiệt sức",D8<>"Bình thường",D8<>"Đủ sức"),"Thiếu chế độ",IF(AND(LEN(I8)>0,COUNTIF($I$63:$I$69,I8)=0),"Lỗi mã","Hợp lệ"))))))) | K8: =IF(AND(ISNUMBER(B8),B8>=0,B8<=24),1,0) -> 0 | L8: =IF(ISNUMBER(C8),IF(AND(C8>=1,C8<=5,MOD(C8,1)=0),1,0),0) -> 0 | M8: =IF(AND(J8="Hợp lệ",ISNUMBER(F8)),1,0) -> 0 | N8: =IF(AND(J8="Hợp lệ",ISNUMBER(G8)),1,0) -> 0 | O8: =IF(J8="Hợp lệ",1,0) -> 0
A9: 46311 | J9: =IF(AND(COUNTA(B9:I9)=0),"",IF(OR(AND(NOT(ISBLANK(B9)),OR(NOT(ISNUMBER(B9)),B9<0,B9>24)),AND(NOT(ISBLANK(C9)),IF(ISNUMBER(C9),OR(C9<1,C9>5,MOD(C9,1)<>0),TRUE))),"Lỗi ngủ/mệt",IF(NOT(ISNUMBER(E9)),"Thiếu tổng phút",IF(OR(E9<0,OR(AND(NOT(ISBLANK(F9)),OR(NOT(ISNUMBER(F9)),F9<0)),AND(NOT(ISBLANK(G9)),OR(NOT(ISNUMBER(G9)),G9<0)))),"Lỗi phút",IF(SUM(F9:G9)>E9,"Nghe+nói vượt tổng",IF(AND(D9<>"Nghỉ",D9<>"Kiệt sức",D9<>"Bình thường",D9<>"Đủ sức"),"Thiếu chế độ",IF(AND(LEN(I9)>0,COUNTIF($I$63:$I$69,I9)=0),"Lỗi mã","Hợp lệ"))))))) | K9: =IF(AND(ISNUMBER(B9),B9>=0,B9<=24),1,0) -> 0 | L9: =IF(ISNUMBER(C9),IF(AND(C9>=1,C9<=5,MOD(C9,1)=0),1,0),0) -> 0 | M9: =IF(AND(J9="Hợp lệ",ISNUMBER(F9)),1,0) -> 0 | N9: =IF(AND(J9="Hợp lệ",ISNUMBER(G9)),1,0) -> 0 | O9: =IF(J9="Hợp lệ",1,0) -> 0
A10: 46312 | J10: =IF(AND(COUNTA(B10:I10)=0),"",IF(OR(AND(NOT(ISBLANK(B10)),OR(NOT(ISNUMBER(B10)),B10<0,B10>24)),AND(NOT(ISBLANK(C10)),IF(ISNUMBER(C10),OR(C10<1,C10>5,MOD(C10,1)<>0),TRUE))),"Lỗi ngủ/mệt",IF(NOT(ISNUMBER(E10)),"Thiếu tổng phút",IF(OR(E10<0,OR(AND(NOT(ISBLANK(F10)),OR(NOT(ISNUMBER(F10)),F10<0)),AND(NOT(ISBLANK(G10)),OR(NOT(ISNUMBER(G10)),G10<0)))),"Lỗi phút",IF(SUM(F10:G10)>E10,"Nghe+nói vượt tổng",IF(AND(D10<>"Nghỉ",D10<>"Kiệt sức",D10<>"Bình thường",D10<>"Đủ sức"),"Thiếu chế độ",IF(AND(LEN(I10)>0,COUNTIF($I$63:$I$69,I10)=0),"Lỗi mã","Hợp lệ"))))))) | K10: =IF(AND(ISNUMBER(B10),B10>=0,B10<=24),1,0) -> 0 | L10: =IF(ISNUMBER(C10),IF(AND(C10>=1,C10<=5,MOD(C10,1)=0),1,0),0) -> 0 | M10: =IF(AND(J10="Hợp lệ",ISNUMBER(F10)),1,0) -> 0 | N10: =IF(AND(J10="Hợp lệ",ISNUMBER(G10)),1,0) -> 0 | O10: =IF(J10="Hợp lệ",1,0) -> 0
A11: 46313 | J11: =IF(AND(COUNTA(B11:I11)=0),"",IF(OR(AND(NOT(ISBLANK(B11)),OR(NOT(ISNUMBER(B11)),B11<0,B11>24)),AND(NOT(ISBLANK(C11)),IF(ISNUMBER(C11),OR(C11<1,C11>5,MOD(C11,1)<>0),TRUE))),"Lỗi ngủ/mệt",IF(NOT(ISNUMBER(E11)),"Thiếu tổng phút",IF(OR(E11<0,OR(AND(NOT(ISBLANK(F11)),OR(NOT(ISNUMBER(F11)),F11<0)),AND(NOT(ISBLANK(G11)),OR(NOT(ISNUMBER(G11)),G11<0)))),"Lỗi phút",IF(SUM(F11:G11)>E11,"Nghe+nói vượt tổng",IF(AND(D11<>"Nghỉ",D11<>"Kiệt sức",D11<>"Bình thường",D11<>"Đủ sức"),"Thiếu chế độ",IF(AND(LEN(I11)>0,COUNTIF($I$63:$I$69,I11)=0),"Lỗi mã","Hợp lệ"))))))) | K11: =IF(AND(ISNUMBER(B11),B11>=0,B11<=24),1,0) -> 0 | L11: =IF(ISNUMBER(C11),IF(AND(C11>=1,C11<=5,MOD(C11,1)=0),1,0),0) -> 0 | M11: =IF(AND(J11="Hợp lệ",ISNUMBER(F11)),1,0) -> 0 | N11: =IF(AND(J11="Hợp lệ",ISNUMBER(G11)),1,0) -> 0 | O11: =IF(J11="Hợp lệ",1,0) -> 0
A12: 46314 | J12: =IF(AND(COUNTA(B12:I12)=0),"",IF(OR(AND(NOT(ISBLANK(B12)),OR(NOT(ISNUMBER(B12)),B12<0,B12>24)),AND(NOT(ISBLANK(C12)),IF(ISNUMBER(C12),OR(C12<1,C12>5,MOD(C12,1)<>0),TRUE))),"Lỗi ngủ/mệt",IF(NOT(ISNUMBER(E12)),"Thiếu tổng phút",IF(OR(E12<0,OR(AND(NOT(ISBLANK(F12)),OR(NOT(ISNUMBER(F12)),F12<0)),AND(NOT(ISBLANK(G12)),OR(NOT(ISNUMBER(G12)),G12<0)))),"Lỗi phút",IF(SUM(F12:G12)>E12,"Nghe+nói vượt tổng",IF(AND(D12<>"Nghỉ",D12<>"Kiệt sức",D12<>"Bình thường",D12<>"Đủ sức"),"Thiếu chế độ",IF(AND(LEN(I12)>0,COUNTIF($I$63:$I$69,I12)=0),"Lỗi mã","Hợp lệ"))))))) | K12: =IF(AND(ISNUMBER(B12),B12>=0,B12<=24),1,0) -> 0 | L12: =IF(ISNUMBER(C12),IF(AND(C12>=1,C12<=5,MOD(C12,1)=0),1,0),0) -> 0 | M12: =IF(AND(J12="Hợp lệ",ISNUMBER(F12)),1,0) -> 0 | N12: =IF(AND(J12="Hợp lệ",ISNUMBER(G12)),1,0) -> 0 | O12: =IF(J12="Hợp lệ",1,0) -> 0
A13: 46315 | J13: =IF(AND(COUNTA(B13:I13)=0),"",IF(OR(AND(NOT(ISBLANK(B13)),OR(NOT(ISNUMBER(B13)),B13<0,B13>24)),AND(NOT(ISBLANK(C13)),IF(ISNUMBER(C13),OR(C13<1,C13>5,MOD(C13,1)<>0),TRUE))),"Lỗi ngủ/mệt",IF(NOT(ISNUMBER(E13)),"Thiếu tổng phút",IF(OR(E13<0,OR(AND(NOT(ISBLANK(F13)),OR(NOT(ISNUMBER(F13)),F13<0)),AND(NOT(ISBLANK(G13)),OR(NOT(ISNUMBER(G13)),G13<0)))),"Lỗi phút",IF(SUM(F13:G13)>E13,"Nghe+nói vượt tổng",IF(AND(D13<>"Nghỉ",D13<>"Kiệt sức",D13<>"Bình thường",D13<>"Đủ sức"),"Thiếu chế độ",IF(AND(LEN(I13)>0,COUNTIF($I$63:$I$69,I13)=0),"Lỗi mã","Hợp lệ"))))))) | K13: =IF(AND(ISNUMBER(B13),B13>=0,B13<=24),1,0) -> 0 | L13: =IF(ISNUMBER(C13),IF(AND(C13>=1,C13<=5,MOD(C13,1)=0),1,0),0) -> 0 | M13: =IF(AND(J13="Hợp lệ",ISNUMBER(F13)),1,0) -> 0 | N13: =IF(AND(J13="Hợp lệ",ISNUMBER(G13)),1,0) -> 0 | O13: =IF(J13="Hợp lệ",1,0) -> 0
A14: 46316 | J14: =IF(AND(COUNTA(B14:I14)=0),"",IF(OR(AND(NOT(ISBLANK(B14)),OR(NOT(ISNUMBER(B14)),B14<0,B14>24)),AND(NOT(ISBLANK(C14)),IF(ISNUMBER(C14),OR(C14<1,C14>5,MOD(C14,1)<>0),TRUE))),"Lỗi ngủ/mệt",IF(NOT(ISNUMBER(E14)),"Thiếu tổng phút",IF(OR(E14<0,OR(AND(NOT(ISBLANK(F14)),OR(NOT(ISNUMBER(F14)),F14<0)),AND(NOT(ISBLANK(G14)),OR(NOT(ISNUMBER(G14)),G14<0)))),"Lỗi phút",IF(SUM(F14:G14)>E14,"Nghe+nói vượt tổng",IF(AND(D14<>"Nghỉ",D14<>"Kiệt sức",D14<>"Bình thường",D14<>"Đủ sức"),"Thiếu chế độ",IF(AND(LEN(I14)>0,COUNTIF($I$63:$I$69,I14)=0),"Lỗi mã","Hợp lệ"))))))) | K14: =IF(AND(ISNUMBER(B14),B14>=0,B14<=24),1,0) -> 0 | L14: =IF(ISNUMBER(C14),IF(AND(C14>=1,C14<=5,MOD(C14,1)=0),1,0),0) -> 0 | M14: =IF(AND(J14="Hợp lệ",ISNUMBER(F14)),1,0) -> 0 | N14: =IF(AND(J14="Hợp lệ",ISNUMBER(G14)),1,0) -> 0 | O14: =IF(J14="Hợp lệ",1,0) -> 0
A15: 46317 | J15: =IF(AND(COUNTA(B15:I15)=0),"",IF(OR(AND(NOT(ISBLANK(B15)),OR(NOT(ISNUMBER(B15)),B15<0,B15>24)),AND(NOT(ISBLANK(C15)),IF(ISNUMBER(C15),OR(C15<1,C15>5,MOD(C15,1)<>0),TRUE))),"Lỗi ngủ/mệt",IF(NOT(ISNUMBER(E15)),"Thiếu tổng phút",IF(OR(E15<0,OR(AND(NOT(ISBLANK(F15)),OR(NOT(ISNUMBER(F15)),F15<0)),AND(NOT(ISBLANK(G15)),OR(NOT(ISNUMBER(G15)),G15<0)))),"Lỗi phút",IF(SUM(F15:G15)>E15,"Nghe+nói vượt tổng",IF(AND(D15<>"Nghỉ",D15<>"Kiệt sức",D15<>"Bình thường",D15<>"Đủ sức"),"Thiếu chế độ",IF(AND(LEN(I15)>0,COUNTIF($I$63:$I$69,I15)=0),"Lỗi mã","Hợp lệ"))))))) | K15: =IF(AND(ISNUMBER(B15),B15>=0,B15<=24),1,0) -> 0 | L15: =IF(ISNUMBER(C15),IF(AND(C15>=1,C15<=5,MOD(C15,1)=0),1,0),0) -> 0 | M15: =IF(AND(J15="Hợp lệ",ISNUMBER(F15)),1,0) -> 0 | N15: =IF(AND(J15="Hợp lệ",ISNUMBER(G15)),1,0) -> 0 | O15: =IF(J15="Hợp lệ",1,0) -> 0
A16: 46318 | J16: =IF(AND(COUNTA(B16:I16)=0),"",IF(OR(AND(NOT(ISBLANK(B16)),OR(NOT(ISNUMBER(B16)),B16<0,B16>24)),AND(NOT(ISBLANK(C16)),IF(ISNUMBER(C16),OR(C16<1,C16>5,MOD(C16,1)<>0),TRUE))),"Lỗi ngủ/mệt",IF(NOT(ISNUMBER(E16)),"Thiếu tổng phút",IF(OR(E16<0,OR(AND(NOT(ISBLANK(F16)),OR(NOT(ISNUMBER(F16)),F16<0)),AND(NOT(ISBLANK(G16)),OR(NOT(ISNUMBER(G16)),G16<0)))),"Lỗi phút",IF(SUM(F16:G16)>E16,"Nghe+nói vượt tổng",IF(AND(D16<>"Nghỉ",D16<>"Kiệt sức",D16<>"Bình thường",D16<>"Đủ sức"),"Thiếu chế độ",IF(AND(LEN(I16)>0,COUNTIF($I$63:$I$69,I16)=0),"Lỗi mã","Hợp lệ"))))))) | K16: =IF(AND(ISNUMBER(B16),B16>=0,B16<=24),1,0) -> 0 | L16: =IF(ISNUMBER(C16),IF(AND(C16>=1,C16<=5,MOD(C16,1)=0),1,0),0) -> 0 | M16: =IF(AND(J16="Hợp lệ",ISNUMBER(F16)),1,0) -> 0 | N16: =IF(AND(J16="Hợp lệ",ISNUMBER(G16)),1,0) -> 0 | O16: =IF(J16="Hợp lệ",1,0) -> 0
A17: 46319 | J17: =IF(AND(COUNTA(B17:I17)=0),"",IF(OR(AND(NOT(ISBLANK(B17)),OR(NOT(ISNUMBER(B17)),B17<0,B17>24)),AND(NOT(ISBLANK(C17)),IF(ISNUMBER(C17),OR(C17<1,C17>5,MOD(C17,1)<>0),TRUE))),"Lỗi ngủ/mệt",IF(NOT(ISNUMBER(E17)),"Thiếu tổng phút",IF(OR(E17<0,OR(AND(NOT(ISBLANK(F17)),OR(NOT(ISNUMBER(F17)),F17<0)),AND(NOT(ISBLANK(G17)),OR(NOT(ISNUMBER(G17)),G17<0)))),"Lỗi phút",IF(SUM(F17:G17)>E17,"Nghe+nói vượt tổng",IF(AND(D17<>"Nghỉ",D17<>"Kiệt sức",D17<>"Bình thường",D17<>"Đủ sức"),"Thiếu chế độ",IF(AND(LEN(I17)>0,COUNTIF($I$63:$I$69,I17)=0),"Lỗi mã","Hợp lệ"))))))) | K17: =IF(AND(ISNUMBER(B17),B17>=0,B17<=24),1,0) -> 0 | L17: =IF(ISNUMBER(C17),IF(AND(C17>=1,C17<=5,MOD(C17,1)=0),1,0),0) -> 0 | M17: =IF(AND(J17="Hợp lệ",ISNUMBER(F17)),1,0) -> 0 | N17: =IF(AND(J17="Hợp lệ",ISNUMBER(G17)),1,0) -> 0 | O17: =IF(J17="Hợp lệ",1,0) -> 0
A18: 46320 | J18: =IF(AND(COUNTA(B18:I18)=0),"",IF(OR(AND(NOT(ISBLANK(B18)),OR(NOT(ISNUMBER(B18)),B18<0,B18>24)),AND(NOT(ISBLANK(C18)),IF(ISNUMBER(C18),OR(C18<1,C18>5,MOD(C18,1)<>0),TRUE))),"Lỗi ngủ/mệt",IF(NOT(ISNUMBER(E18)),"Thiếu tổng phút",IF(OR(E18<0,OR(AND(NOT(ISBLANK(F18)),OR(NOT(ISNUMBER(F18)),F18<0)),AND(NOT(ISBLANK(G18)),OR(NOT(ISNUMBER(G18)),G18<0)))),"Lỗi phút",IF(SUM(F18:G18)>E18,"Nghe+nói vượt tổng",IF(AND(D18<>"Nghỉ",D18<>"Kiệt sức",D18<>"Bình thường",D18<>"Đủ sức"),"Thiếu chế độ",IF(AND(LEN(I18)>0,COUNTIF($I$63:$I$69,I18)=0),"Lỗi mã","Hợp lệ"))))))) | K18: =IF(AND(ISNUMBER(B18),B18>=0,B18<=24),1,0) -> 0 | L18: =IF(ISNUMBER(C18),IF(AND(C18>=1,C18<=5,MOD(C18,1)=0),1,0),0) -> 0 | M18: =IF(AND(J18="Hợp lệ",ISNUMBER(F18)),1,0) -> 0 | N18: =IF(AND(J18="Hợp lệ",ISNUMBER(G18)),1,0) -> 0 | O18: =IF(J18="Hợp lệ",1,0) -> 0
A19: 46321 | J19: =IF(AND(COUNTA(B19:I19)=0),"",IF(OR(AND(NOT(ISBLANK(B19)),OR(NOT(ISNUMBER(B19)),B19<0,B19>24)),AND(NOT(ISBLANK(C19)),IF(ISNUMBER(C19),OR(C19<1,C19>5,MOD(C19,1)<>0),TRUE))),"Lỗi ngủ/mệt",IF(NOT(ISNUMBER(E19)),"Thiếu tổng phút",IF(OR(E19<0,OR(AND(NOT(ISBLANK(F19)),OR(NOT(ISNUMBER(F19)),F19<0)),AND(NOT(ISBLANK(G19)),OR(NOT(ISNUMBER(G19)),G19<0)))),"Lỗi phút",IF(SUM(F19:G19)>E19,"Nghe+nói vượt tổng",IF(AND(D19<>"Nghỉ",D19<>"Kiệt sức",D19<>"Bình thường",D19<>"Đủ sức"),"Thiếu chế độ",IF(AND(LEN(I19)>0,COUNTIF($I$63:$I$69,I19)=0),"Lỗi mã","Hợp lệ"))))))) | K19: =IF(AND(ISNUMBER(B19),B19>=0,B19<=24),1,0) -> 0 | L19: =IF(ISNUMBER(C19),IF(AND(C19>=1,C19<=5,MOD(C19,1)=0),1,0),0) -> 0 | M19: =IF(AND(J19="Hợp lệ",ISNUMBER(F19)),1,0) -> 0 | N19: =IF(AND(J19="Hợp lệ",ISNUMBER(G19)),1,0) -> 0 | O19: =IF(J19="Hợp lệ",1,0) -> 0
... A59: 46361 | J59: =IF(AND(COUNTA(B59:I59)=0),"",IF(OR(AND(NOT(ISBLANK(B59)),OR(NOT(ISNUMBER(B59)),B59<0,B59>24)),AND(NOT(ISBLANK(C59)),IF(ISNUMBER(C59),OR(C59<1,C59>5,MOD(C59,1)<>0),TRUE))),"Lỗi ngủ/mệt",IF(NOT(ISNUMBER(E59)),"Thiếu tổng phút",IF(OR(E59<0,OR(AND(NOT(ISBLANK(F59)),OR(NOT(ISNUMBER(F59)),F59<0)),AND(NOT(ISBLANK(G59)),OR(NOT(ISNUMBER(G59)),G59<0)))),"Lỗi phút",IF(SUM(F59:G59)>E59,"Nghe+nói vượt tổng",IF(AND(D59<>"Nghỉ",D59<>"Kiệt sức",D59<>"Bình thường",D59<>"Đủ sức"),"Thiếu chế độ",IF(AND(LEN(I59)>0,COUNTIF($I$63:$I$69,I59)=0),"Lỗi mã","Hợp lệ"))))))) | K59: =IF(AND(ISNUMBER(B59),B59>=0,B59<=24),1,0) -> 0 | L59: =IF(ISNUMBER(C59),IF(AND(C59>=1,C59<=5,MOD(C59,1)=0),1,0),0) -> 0 | M59: =IF(AND(J59="Hợp lệ",ISNUMBER(F59)),1,0) -> 0 | N59: =IF(AND(J59="Hợp lệ",ISNUMBER(G59)),1,0) -> 0 | O59: =IF(J59="Hợp lệ",1,0) -> 0
I62: Mã | J62: Ý nghĩa
I63: V | J63: Từ và kanji
I64: G | J64: Ngữ pháp
I65: R | J65: Nối ý đọc
I66: A | J66: Nhận diện âm
I67: M | J67: Giữ thông tin
I68: T | J68: Thời gian
I69: F | J69: Mệt/gián đoạn

Sheet Đo năng lực
A2: Đo năng lực bằng câu mới và ôn lại lỗi
A4: Tỷ lệ đúng thô không đổi thành điểm JLPT. Chỉ dùng các hàng Mới để quyết định tăng độ khó.
A5: Ô vàng tự nhập; sửa ngày dự kiến theo ngày thật. START18 cuối bảng tự tổng hợp, không nhập lặp.
A6: Chỉ hàng Mới, hợp lệ đi vào tổng hợp tuần. K là mã lỗi; L nêu dữ liệu cần sửa. Không đổi sang điểm JLPT.
A7: Ngày đo | B7: Cấp | C7: Kỹ năng | D7: Mã cuốn / phần / câu | E7: Loại câu | F7: Số đúng | G7: Tổng câu | H7: Phút làm | I7: Tỷ lệ đúng | J7: Lỗi chính hoặc quyết định | K7: Mã lỗi chính | L7: Kiểm tra dòng
A8: 46310 | B8: N4 | C8: Từ và kanji | I8: =IF(OR(ISBLANK(F8),ISBLANK(G8)),"",IF(OR(NOT(ISNUMBER(F8)),NOT(ISNUMBER(G8))),"Lỗi nhập",IF(OR(G8<=0,F8<0,F8>G8),"Lỗi nhập",F8/G8))) | L8: =IF(NOT(OR(COUNT(F8:H8)>0,LEN(F8&G8&H8)>0)),"",IF(NOT(ISNUMBER(I8)),"Lỗi/thiếu số đúng-tổng",IF(OR(MOD(F8,1)<>0,MOD(G8,1)<>0),"Lỗi/thiếu số đúng-tổng",IF(OR(AND(B8<>"N4",B8<>"N3",B8<>"N2"),AND(C8<>"Từ và kanji",C8<>"Ngữ pháp",C8<>"Đọc",C8<>"Nghe")),"Sai cấp/kỹ năng",IF(OR(NOT(ISNUMBER(A8)),A8<1),"Thiếu ngày đo",IF(D8="","Thiếu mã bài",IF(AND(E8<>"Mới",E8<>"Ôn lại"),"Thiếu loại câu",IF(OR(NOT(ISNUMBER(H8)),H8<=0),"Thiếu phút",IF(AND(E8="Mới",COUNTIFS($B$8:$B$79,B8,$C$8:$C$79,C8,$D$8:$D$79,D8,$E$8:$E$79,"Mới",$G$8:$G$79,">0")>1),"Trùng câu mới","Hợp lệ")))))))))
A9: 46310 | B9: N4 | C9: Ngữ pháp | I9: =IF(OR(ISBLANK(F9),ISBLANK(G9)),"",IF(OR(NOT(ISNUMBER(F9)),NOT(ISNUMBER(G9))),"Lỗi nhập",IF(OR(G9<=0,F9<0,F9>G9),"Lỗi nhập",F9/G9))) | L9: =IF(NOT(OR(COUNT(F9:H9)>0,LEN(F9&G9&H9)>0)),"",IF(NOT(ISNUMBER(I9)),"Lỗi/thiếu số đúng-tổng",IF(OR(MOD(F9,1)<>0,MOD(G9,1)<>0),"Lỗi/thiếu số đúng-tổng",IF(OR(AND(B9<>"N4",B9<>"N3",B9<>"N2"),AND(C9<>"Từ và kanji",C9<>"Ngữ pháp",C9<>"Đọc",C9<>"Nghe")),"Sai cấp/kỹ năng",IF(OR(NOT(ISNUMBER(A9)),A9<1),"Thiếu ngày đo",IF(D9="","Thiếu mã bài",IF(AND(E9<>"Mới",E9<>"Ôn lại"),"Thiếu loại câu",IF(OR(NOT(ISNUMBER(H9)),H9<=0),"Thiếu phút",IF(AND(E9="Mới",COUNTIFS($B$8:$B$79,B9,$C$8:$C$79,C9,$D$8:$D$79,D9,$E$8:$E$79,"Mới",$G$8:$G$79,">0")>1),"Trùng câu mới","Hợp lệ")))))))))
A10: 46310 | B10: N4 | C10: Đọc | I10: =IF(OR(ISBLANK(F10),ISBLANK(G10)),"",IF(OR(NOT(ISNUMBER(F10)),NOT(ISNUMBER(G10))),"Lỗi nhập",IF(OR(G10<=0,F10<0,F10>G10),"Lỗi nhập",F10/G10))) | L10: =IF(NOT(OR(COUNT(F10:H10)>0,LEN(F10&G10&H10)>0)),"",IF(NOT(ISNUMBER(I10)),"Lỗi/thiếu số đúng-tổng",IF(OR(MOD(F10,1)<>0,MOD(G10,1)<>0),"Lỗi/thiếu số đúng-tổng",IF(OR(AND(B10<>"N4",B10<>"N3",B10<>"N2"),AND(C10<>"Từ và kanji",C10<>"Ngữ pháp",C10<>"Đọc",C10<>"Nghe")),"Sai cấp/kỹ năng",IF(OR(NOT(ISNUMBER(A10)),A10<1),"Thiếu ngày đo",IF(D10="","Thiếu mã bài",IF(AND(E10<>"Mới",E10<>"Ôn lại"),"Thiếu loại câu",IF(OR(NOT(ISNUMBER(H10)),H10<=0),"Thiếu phút",IF(AND(E10="Mới",COUNTIFS($B$8:$B$79,B10,$C$8:$C$79,C10,$D$8:$D$79,D10,$E$8:$E$79,"Mới",$G$8:$G$79,">0")>1),"Trùng câu mới","Hợp lệ")))))))))
A11: 46310 | B11: N4 | C11: Nghe | I11: =IF(OR(ISBLANK(F11),ISBLANK(G11)),"",IF(OR(NOT(ISNUMBER(F11)),NOT(ISNUMBER(G11))),"Lỗi nhập",IF(OR(G11<=0,F11<0,F11>G11),"Lỗi nhập",F11/G11))) | L11: =IF(NOT(OR(COUNT(F11:H11)>0,LEN(F11&G11&H11)>0)),"",IF(NOT(ISNUMBER(I11)),"Lỗi/thiếu số đúng-tổng",IF(OR(MOD(F11,1)<>0,MOD(G11,1)<>0),"Lỗi/thiếu số đúng-tổng",IF(OR(AND(B11<>"N4",B11<>"N3",B11<>"N2"),AND(C11<>"Từ và kanji",C11<>"Ngữ pháp",C11<>"Đọc",C11<>"Nghe")),"Sai cấp/kỹ năng",IF(OR(NOT(ISNUMBER(A11)),A11<1),"Thiếu ngày đo",IF(D11="","Thiếu mã bài",IF(AND(E11<>"Mới",E11<>"Ôn lại"),"Thiếu loại câu",IF(OR(NOT(ISNUMBER(H11)),H11<=0),"Thiếu phút",IF(AND(E11="Mới",COUNTIFS($B$8:$B$79,B11,$C$8:$C$79,C11,$D$8:$D$79,D11,$E$8:$E$79,"Mới",$G$8:$G$79,">0")>1),"Trùng câu mới","Hợp lệ")))))))))
A12: 46310 | B12: N3 | C12: Từ và kanji | I12: =IF(OR(ISBLANK(F12),ISBLANK(G12)),"",IF(OR(NOT(ISNUMBER(F12)),NOT(ISNUMBER(G12))),"Lỗi nhập",IF(OR(G12<=0,F12<0,F12>G12),"Lỗi nhập",F12/G12))) | L12: =IF(NOT(OR(COUNT(F12:H12)>0,LEN(F12&G12&H12)>0)),"",IF(NOT(ISNUMBER(I12)),"Lỗi/thiếu số đúng-tổng",IF(OR(MOD(F12,1)<>0,MOD(G12,1)<>0),"Lỗi/thiếu số đúng-tổng",IF(OR(AND(B12<>"N4",B12<>"N3",B12<>"N2"),AND(C12<>"Từ và kanji",C12<>"Ngữ pháp",C12<>"Đọc",C12<>"Nghe")),"Sai cấp/kỹ năng",IF(OR(NOT(ISNUMBER(A12)),A12<1),"Thiếu ngày đo",IF(D12="","Thiếu mã bài",IF(AND(E12<>"Mới",E12<>"Ôn lại"),"Thiếu loại câu",IF(OR(NOT(ISNUMBER(H12)),H12<=0),"Thiếu phút",IF(AND(E12="Mới",COUNTIFS($B$8:$B$79,B12,$C$8:$C$79,C12,$D$8:$D$79,D12,$E$8:$E$79,"Mới",$G$8:$G$79,">0")>1),"Trùng câu mới","Hợp lệ")))))))))
A13: 46310 | B13: N3 | C13: Ngữ pháp | I13: =IF(OR(ISBLANK(F13),ISBLANK(G13)),"",IF(OR(NOT(ISNUMBER(F13)),NOT(ISNUMBER(G13))),"Lỗi nhập",IF(OR(G13<=0,F13<0,F13>G13),"Lỗi nhập",F13/G13))) | L13: =IF(NOT(OR(COUNT(F13:H13)>0,LEN(F13&G13&H13)>0)),"",IF(NOT(ISNUMBER(I13)),"Lỗi/thiếu số đúng-tổng",IF(OR(MOD(F13,1)<>0,MOD(G13,1)<>0),"Lỗi/thiếu số đúng-tổng",IF(OR(AND(B13<>"N4",B13<>"N3",B13<>"N2"),AND(C13<>"Từ và kanji",C13<>"Ngữ pháp",C13<>"Đọc",C13<>"Nghe")),"Sai cấp/kỹ năng",IF(OR(NOT(ISNUMBER(A13)),A13<1),"Thiếu ngày đo",IF(D13="","Thiếu mã bài",IF(AND(E13<>"Mới",E13<>"Ôn lại"),"Thiếu loại câu",IF(OR(NOT(ISNUMBER(H13)),H13<=0),"Thiếu phút",IF(AND(E13="Mới",COUNTIFS($B$8:$B$79,B13,$C$8:$C$79,C13,$D$8:$D$79,D13,$E$8:$E$79,"Mới",$G$8:$G$79,">0")>1),"Trùng câu mới","Hợp lệ")))))))))
A14: 46310 | B14: N3 | C14: Đọc | I14: =IF(OR(ISBLANK(F14),ISBLANK(G14)),"",IF(OR(NOT(ISNUMBER(F14)),NOT(ISNUMBER(G14))),"Lỗi nhập",IF(OR(G14<=0,F14<0,F14>G14),"Lỗi nhập",F14/G14))) | L14: =IF(NOT(OR(COUNT(F14:H14)>0,LEN(F14&G14&H14)>0)),"",IF(NOT(ISNUMBER(I14)),"Lỗi/thiếu số đúng-tổng",IF(OR(MOD(F14,1)<>0,MOD(G14,1)<>0),"Lỗi/thiếu số đúng-tổng",IF(OR(AND(B14<>"N4",B14<>"N3",B14<>"N2"),AND(C14<>"Từ và kanji",C14<>"Ngữ pháp",C14<>"Đọc",C14<>"Nghe")),"Sai cấp/kỹ năng",IF(OR(NOT(ISNUMBER(A14)),A14<1),"Thiếu ngày đo",IF(D14="","Thiếu mã bài",IF(AND(E14<>"Mới",E14<>"Ôn lại"),"Thiếu loại câu",IF(OR(NOT(ISNUMBER(H14)),H14<=0),"Thiếu phút",IF(AND(E14="Mới",COUNTIFS($B$8:$B$79,B14,$C$8:$C$79,C14,$D$8:$D$79,D14,$E$8:$E$79,"Mới",$G$8:$G$79,">0")>1),"Trùng câu mới","Hợp lệ")))))))))
A15: 46310 | B15: N3 | C15: Nghe | I15: =IF(OR(ISBLANK(F15),ISBLANK(G15)),"",IF(OR(NOT(ISNUMBER(F15)),NOT(ISNUMBER(G15))),"Lỗi nhập",IF(OR(G15<=0,F15<0,F15>G15),"Lỗi nhập",F15/G15))) | L15: =IF(NOT(OR(COUNT(F15:H15)>0,LEN(F15&G15&H15)>0)),"",IF(NOT(ISNUMBER(I15)),"Lỗi/thiếu số đúng-tổng",IF(OR(MOD(F15,1)<>0,MOD(G15,1)<>0),"Lỗi/thiếu số đúng-tổng",IF(OR(AND(B15<>"N4",B15<>"N3",B15<>"N2"),AND(C15<>"Từ và kanji",C15<>"Ngữ pháp",C15<>"Đọc",C15<>"Nghe")),"Sai cấp/kỹ năng",IF(OR(NOT(ISNUMBER(A15)),A15<1),"Thiếu ngày đo",IF(D15="","Thiếu mã bài",IF(AND(E15<>"Mới",E15<>"Ôn lại"),"Thiếu loại câu",IF(OR(NOT(ISNUMBER(H15)),H15<=0),"Thiếu phút",IF(AND(E15="Mới",COUNTIFS($B$8:$B$79,B15,$C$8:$C$79,C15,$D$8:$D$79,D15,$E$8:$E$79,"Mới",$G$8:$G$79,">0")>1),"Trùng câu mới","Hợp lệ")))))))))
A16: 46317 | B16: N4 | C16: Từ và kanji | I16: =IF(OR(ISBLANK(F16),ISBLANK(G16)),"",IF(OR(NOT(ISNUMBER(F16)),NOT(ISNUMBER(G16))),"Lỗi nhập",IF(OR(G16<=0,F16<0,F16>G16),"Lỗi nhập",F16/G16))) | L16: =IF(NOT(OR(COUNT(F16:H16)>0,LEN(F16&G16&H16)>0)),"",IF(NOT(ISNUMBER(I16)),"Lỗi/thiếu số đúng-tổng",IF(OR(MOD(F16,1)<>0,MOD(G16,1)<>0),"Lỗi/thiếu số đúng-tổng",IF(OR(AND(B16<>"N4",B16<>"N3",B16<>"N2"),AND(C16<>"Từ và kanji",C16<>"Ngữ pháp",C16<>"Đọc",C16<>"Nghe")),"Sai cấp/kỹ năng",IF(OR(NOT(ISNUMBER(A16)),A16<1),"Thiếu ngày đo",IF(D16="","Thiếu mã bài",IF(AND(E16<>"Mới",E16<>"Ôn lại"),"Thiếu loại câu",IF(OR(NOT(ISNUMBER(H16)),H16<=0),"Thiếu phút",IF(AND(E16="Mới",COUNTIFS($B$8:$B$79,B16,$C$8:$C$79,C16,$D$8:$D$79,D16,$E$8:$E$79,"Mới",$G$8:$G$79,">0")>1),"Trùng câu mới","Hợp lệ")))))))))
A17: 46317 | B17: N4 | C17: Ngữ pháp | I17: =IF(OR(ISBLANK(F17),ISBLANK(G17)),"",IF(OR(NOT(ISNUMBER(F17)),NOT(ISNUMBER(G17))),"Lỗi nhập",IF(OR(G17<=0,F17<0,F17>G17),"Lỗi nhập",F17/G17))) | L17: =IF(NOT(OR(COUNT(F17:H17)>0,LEN(F17&G17&H17)>0)),"",IF(NOT(ISNUMBER(I17)),"Lỗi/thiếu số đúng-tổng",IF(OR(MOD(F17,1)<>0,MOD(G17,1)<>0),"Lỗi/thiếu số đúng-tổng",IF(OR(AND(B17<>"N4",B17<>"N3",B17<>"N2"),AND(C17<>"Từ và kanji",C17<>"Ngữ pháp",C17<>"Đọc",C17<>"Nghe")),"Sai cấp/kỹ năng",IF(OR(NOT(ISNUMBER(A17)),A17<1),"Thiếu ngày đo",IF(D17="","Thiếu mã bài",IF(AND(E17<>"Mới",E17<>"Ôn lại"),"Thiếu loại câu",IF(OR(NOT(ISNUMBER(H17)),H17<=0),"Thiếu phút",IF(AND(E17="Mới",COUNTIFS($B$8:$B$79,B17,$C$8:$C$79,C17,$D$8:$D$79,D17,$E$8:$E$79,"Mới",$G$8:$G$79,">0")>1),"Trùng câu mới","Hợp lệ")))))))))
A18: 46317 | B18: N4 | C18: Đọc | I18: =IF(OR(ISBLANK(F18),ISBLANK(G18)),"",IF(OR(NOT(ISNUMBER(F18)),NOT(ISNUMBER(G18))),"Lỗi nhập",IF(OR(G18<=0,F18<0,F18>G18),"Lỗi nhập",F18/G18))) | L18: =IF(NOT(OR(COUNT(F18:H18)>0,LEN(F18&G18&H18)>0)),"",IF(NOT(ISNUMBER(I18)),"Lỗi/thiếu số đúng-tổng",IF(OR(MOD(F18,1)<>0,MOD(G18,1)<>0),"Lỗi/thiếu số đúng-tổng",IF(OR(AND(B18<>"N4",B18<>"N3",B18<>"N2"),AND(C18<>"Từ và kanji",C18<>"Ngữ pháp",C18<>"Đọc",C18<>"Nghe")),"Sai cấp/kỹ năng",IF(OR(NOT(ISNUMBER(A18)),A18<1),"Thiếu ngày đo",IF(D18="","Thiếu mã bài",IF(AND(E18<>"Mới",E18<>"Ôn lại"),"Thiếu loại câu",IF(OR(NOT(ISNUMBER(H18)),H18<=0),"Thiếu phút",IF(AND(E18="Mới",COUNTIFS($B$8:$B$79,B18,$C$8:$C$79,C18,$D$8:$D$79,D18,$E$8:$E$79,"Mới",$G$8:$G$79,">0")>1),"Trùng câu mới","Hợp lệ")))))))))
A19: 46317 | B19: N4 | C19: Nghe | I19: =IF(OR(ISBLANK(F19),ISBLANK(G19)),"",IF(OR(NOT(ISNUMBER(F19)),NOT(ISNUMBER(G19))),"Lỗi nhập",IF(OR(G19<=0,F19<0,F19>G19),"Lỗi nhập",F19/G19))) | L19: =IF(NOT(OR(COUNT(F19:H19)>0,LEN(F19&G19&H19)>0)),"",IF(NOT(ISNUMBER(I19)),"Lỗi/thiếu số đúng-tổng",IF(OR(MOD(F19,1)<>0,MOD(G19,1)<>0),"Lỗi/thiếu số đúng-tổng",IF(OR(AND(B19<>"N4",B19<>"N3",B19<>"N2"),AND(C19<>"Từ và kanji",C19<>"Ngữ pháp",C19<>"Đọc",C19<>"Nghe")),"Sai cấp/kỹ năng",IF(OR(NOT(ISNUMBER(A19)),A19<1),"Thiếu ngày đo",IF(D19="","Thiếu mã bài",IF(AND(E19<>"Mới",E19<>"Ôn lại"),"Thiếu loại câu",IF(OR(NOT(ISNUMBER(H19)),H19<=0),"Thiếu phút",IF(AND(E19="Mới",COUNTIFS($B$8:$B$79,B19,$C$8:$C$79,C19,$D$8:$D$79,D19,$E$8:$E$79,"Mới",$G$8:$G$79,">0")>1),"Trùng câu mới","Hợp lệ")))))))))
... A71: 46359 | B71: N3 | C71: Nghe | I71: =IF(OR(ISBLANK(F71),ISBLANK(G71)),"",IF(OR(NOT(ISNUMBER(F71)),NOT(ISNUMBER(G71))),"Lỗi nhập",IF(OR(G71<=0,F71<0,F71>G71),"Lỗi nhập",F71/G71))) | L71: =IF(NOT(OR(COUNT(F71:H71)>0,LEN(F71&G71&H71)>0)),"",IF(NOT(ISNUMBER(I71)),"Lỗi/thiếu số đúng-tổng",IF(OR(MOD(F71,1)<>0,MOD(G71,1)<>0),"Lỗi/thiếu số đúng-tổng",IF(OR(AND(B71<>"N4",B71<>"N3",B71<>"N2"),AND(C71<>"Từ và kanji",C71<>"Ngữ pháp",C71<>"Đọc",C71<>"Nghe")),"Sai cấp/kỹ năng",IF(OR(NOT(ISNUMBER(A71)),A71<1),"Thiếu ngày đo",IF(D71="","Thiếu mã bài",IF(AND(E71<>"Mới",E71<>"Ôn lại"),"Thiếu loại câu",IF(OR(NOT(ISNUMBER(H71)),H71<=0),"Thiếu phút",IF(AND(E71="Mới",COUNTIFS($B$8:$B$79,B71,$C$8:$C$79,C71,$D$8:$D$79,D71,$E$8:$E$79,"Mới",$G$8:$G$79,">0")>1),"Trùng câu mới","Hợp lệ")))))))))
A72: =IF(AND('Làm nhanh'!P174="Đã chấm"),MAX('Làm nhanh'!M174),"") | B72: N4 | C72: Từ và kanji | D72: START18-N4-V | E72: =IF(AND('Làm nhanh'!P174="Đã chấm"),IF(AND('Làm nhanh'!O174="Mới"),"Mới","Ôn lại"),"") | F72: =IF(AND('Làm nhanh'!P174="Đã chấm"),SUM('Làm nhanh'!L174),"") | G72: =IF(AND('Làm nhanh'!P174="Đã chấm"),SUM('Làm nhanh'!K174),"") | H72: =IF(AND('Làm nhanh'!P174="Đã chấm"),SUM('Làm nhanh'!N174),"") | I72: =IF(COUNT(F72:G72)<2,"",IF(OR(G72<=0,F72<0,F72>G72),"Lỗi nhập",F72/G72)) | L72: =IF(NOT(OR(COUNT(F72:H72)>0,LEN(F72&G72&H72)>0)),"",IF(NOT(ISNUMBER(I72)),"Lỗi/thiếu số đúng-tổng",IF(OR(MOD(F72,1)<>0,MOD(G72,1)<>0),"Lỗi/thiếu số đúng-tổng",IF(OR(AND(B72<>"N4",B72<>"N3",B72<>"N2"),AND(C72<>"Từ và kanji",C72<>"Ngữ pháp",C72<>"Đọc",C72<>"Nghe")),"Sai cấp/kỹ năng",IF(OR(NOT(ISNUMBER(A72)),A72<1),"Thiếu ngày đo",IF(D72="","Thiếu mã bài",IF(AND(E72<>"Mới",E72<>"Ôn lại"),"Thiếu loại câu",IF(OR(NOT(ISNUMBER(H72)),H72<=0),"Thiếu phút",IF(AND(E72="Mới",COUNTIFS($B$8:$B$79,B72,$C$8:$C$79,C72,$D$8:$D$79,D72,$E$8:$E$79,"Mới",$G$8:$G$79,">0")>1),"Trùng câu mới","Hợp lệ")))))))))
A73: =IF(AND('Làm nhanh'!P172="Đã chấm",'Làm nhanh'!P173="Đã chấm"),MAX('Làm nhanh'!M172,'Làm nhanh'!M173),"") | B73: N4 | C73: Ngữ pháp | D73: START18-N4-G | E73: =IF(AND('Làm nhanh'!P172="Đã chấm",'Làm nhanh'!P173="Đã chấm"),IF(AND('Làm nhanh'!O172="Mới",'Làm nhanh'!O173="Mới"),"Mới","Ôn lại"),"") | F73: =IF(AND('Làm nhanh'!P172="Đã chấm",'Làm nhanh'!P173="Đã chấm"),SUM('Làm nhanh'!L172,'Làm nhanh'!L173),"") | G73: =IF(AND('Làm nhanh'!P172="Đã chấm",'Làm nhanh'!P173="Đã chấm"),SUM('Làm nhanh'!K172,'Làm nhanh'!K173),"") | H73: =IF(AND('Làm nhanh'!P172="Đã chấm",'Làm nhanh'!P173="Đã chấm"),SUM('Làm nhanh'!N172,'Làm nhanh'!N173),"") | I73: =IF(COUNT(F73:G73)<2,"",IF(OR(G73<=0,F73<0,F73>G73),"Lỗi nhập",F73/G73)) | L73: =IF(NOT(OR(COUNT(F73:H73)>0,LEN(F73&G73&H73)>0)),"",IF(NOT(ISNUMBER(I73)),"Lỗi/thiếu số đúng-tổng",IF(OR(MOD(F73,1)<>0,MOD(G73,1)<>0),"Lỗi/thiếu số đúng-tổng",IF(OR(AND(B73<>"N4",B73<>"N3",B73<>"N2"),AND(C73<>"Từ và kanji",C73<>"Ngữ pháp",C73<>"Đọc",C73<>"Nghe")),"Sai cấp/kỹ năng",IF(OR(NOT(ISNUMBER(A73)),A73<1),"Thiếu ngày đo",IF(D73="","Thiếu mã bài",IF(AND(E73<>"Mới",E73<>"Ôn lại"),"Thiếu loại câu",IF(OR(NOT(ISNUMBER(H73)),H73<=0),"Thiếu phút",IF(AND(E73="Mới",COUNTIFS($B$8:$B$79,B73,$C$8:$C$79,C73,$D$8:$D$79,D73,$E$8:$E$79,"Mới",$G$8:$G$79,">0")>1),"Trùng câu mới","Hợp lệ")))))))))
A74: =IF(AND('Làm nhanh'!P175="Đã chấm"),MAX('Làm nhanh'!M175),"") | B74: N4 | C74: Đọc | D74: START18-N4-R | E74: =IF(AND('Làm nhanh'!P175="Đã chấm"),IF(AND('Làm nhanh'!O175="Mới"),"Mới","Ôn lại"),"") | F74: =IF(AND('Làm nhanh'!P175="Đã chấm"),SUM('Làm nhanh'!L175),"") | G74: =IF(AND('Làm nhanh'!P175="Đã chấm"),SUM('Làm nhanh'!K175),"") | H74: =IF(AND('Làm nhanh'!P175="Đã chấm"),SUM('Làm nhanh'!N175),"") | I74: =IF(COUNT(F74:G74)<2,"",IF(OR(G74<=0,F74<0,F74>G74),"Lỗi nhập",F74/G74)) | L74: =IF(NOT(OR(COUNT(F74:H74)>0,LEN(F74&G74&H74)>0)),"",IF(NOT(ISNUMBER(I74)),"Lỗi/thiếu số đúng-tổng",IF(OR(MOD(F74,1)<>0,MOD(G74,1)<>0),"Lỗi/thiếu số đúng-tổng",IF(OR(AND(B74<>"N4",B74<>"N3",B74<>"N2"),AND(C74<>"Từ và kanji",C74<>"Ngữ pháp",C74<>"Đọc",C74<>"Nghe")),"Sai cấp/kỹ năng",IF(OR(NOT(ISNUMBER(A74)),A74<1),"Thiếu ngày đo",IF(D74="","Thiếu mã bài",IF(AND(E74<>"Mới",E74<>"Ôn lại"),"Thiếu loại câu",IF(OR(NOT(ISNUMBER(H74)),H74<=0),"Thiếu phút",IF(AND(E74="Mới",COUNTIFS($B$8:$B$79,B74,$C$8:$C$79,C74,$D$8:$D$79,D74,$E$8:$E$79,"Mới",$G$8:$G$79,">0")>1),"Trùng câu mới","Hợp lệ")))))))))
A75: =IF(AND('Làm nhanh'!P176="Đã chấm",'Làm nhanh'!P177="Đã chấm"),MAX('Làm nhanh'!M176,'Làm nhanh'!M177),"") | B75: N4 | C75: Nghe | D75: START18-N4-L | E75: =IF(AND('Làm nhanh'!P176="Đã chấm",'Làm nhanh'!P177="Đã chấm"),IF(AND('Làm nhanh'!O176="Mới",'Làm nhanh'!O177="Mới"),"Mới","Ôn lại"),"") | F75: =IF(AND('Làm nhanh'!P176="Đã chấm",'Làm nhanh'!P177="Đã chấm"),SUM('Làm nhanh'!L176,'Làm nhanh'!L177),"") | G75: =IF(AND('Làm nhanh'!P176="Đã chấm",'Làm nhanh'!P177="Đã chấm"),SUM('Làm nhanh'!K176,'Làm nhanh'!K177),"") | H75: =IF(AND('Làm nhanh'!P176="Đã chấm",'Làm nhanh'!P177="Đã chấm"),SUM('Làm nhanh'!N176,'Làm nhanh'!N177),"") | I75: =IF(COUNT(F75:G75)<2,"",IF(OR(G75<=0,F75<0,F75>G75),"Lỗi nhập",F75/G75)) | L75: =IF(NOT(OR(COUNT(F75:H75)>0,LEN(F75&G75&H75)>0)),"",IF(NOT(ISNUMBER(I75)),"Lỗi/thiếu số đúng-tổng",IF(OR(MOD(F75,1)<>0,MOD(G75,1)<>0),"Lỗi/thiếu số đúng-tổng",IF(OR(AND(B75<>"N4",B75<>"N3",B75<>"N2"),AND(C75<>"Từ và kanji",C75<>"Ngữ pháp",C75<>"Đọc",C75<>"Nghe")),"Sai cấp/kỹ năng",IF(OR(NOT(ISNUMBER(A75)),A75<1),"Thiếu ngày đo",IF(D75="","Thiếu mã bài",IF(AND(E75<>"Mới",E75<>"Ôn lại"),"Thiếu loại câu",IF(OR(NOT(ISNUMBER(H75)),H75<=0),"Thiếu phút",IF(AND(E75="Mới",COUNTIFS($B$8:$B$79,B75,$C$8:$C$79,C75,$D$8:$D$79,D75,$E$8:$E$79,"Mới",$G$8:$G$79,">0")>1),"Trùng câu mới","Hợp lệ")))))))))
A76: =IF(AND('Làm nhanh'!P179="Đã chấm"),MAX('Làm nhanh'!M179),"") | B76: N3 | C76: Từ và kanji | D76: START18-N3-V | E76: =IF(AND('Làm nhanh'!P179="Đã chấm"),IF(AND('Làm nhanh'!O179="Mới"),"Mới","Ôn lại"),"") | F76: =IF(AND('Làm nhanh'!P179="Đã chấm"),SUM('Làm nhanh'!L179),"") | G76: =IF(AND('Làm nhanh'!P179="Đã chấm"),SUM('Làm nhanh'!K179),"") | H76: =IF(AND('Làm nhanh'!P179="Đã chấm"),SUM('Làm nhanh'!N179),"") | I76: =IF(COUNT(F76:G76)<2,"",IF(OR(G76<=0,F76<0,F76>G76),"Lỗi nhập",F76/G76)) | L76: =IF(NOT(OR(COUNT(F76:H76)>0,LEN(F76&G76&H76)>0)),"",IF(NOT(ISNUMBER(I76)),"Lỗi/thiếu số đúng-tổng",IF(OR(MOD(F76,1)<>0,MOD(G76,1)<>0),"Lỗi/thiếu số đúng-tổng",IF(OR(AND(B76<>"N4",B76<>"N3",B76<>"N2"),AND(C76<>"Từ và kanji",C76<>"Ngữ pháp",C76<>"Đọc",C76<>"Nghe")),"Sai cấp/kỹ năng",IF(OR(NOT(ISNUMBER(A76)),A76<1),"Thiếu ngày đo",IF(D76="","Thiếu mã bài",IF(AND(E76<>"Mới",E76<>"Ôn lại"),"Thiếu loại câu",IF(OR(NOT(ISNUMBER(H76)),H76<=0),"Thiếu phút",IF(AND(E76="Mới",COUNTIFS($B$8:$B$79,B76,$C$8:$C$79,C76,$D$8:$D$79,D76,$E$8:$E$79,"Mới",$G$8:$G$79,">0")>1),"Trùng câu mới","Hợp lệ")))))))))
A77: =IF(AND('Làm nhanh'!P178="Đã chấm"),MAX('Làm nhanh'!M178),"") | B77: N3 | C77: Ngữ pháp | D77: START18-N3-G | E77: =IF(AND('Làm nhanh'!P178="Đã chấm"),IF(AND('Làm nhanh'!O178="Mới"),"Mới","Ôn lại"),"") | F77: =IF(AND('Làm nhanh'!P178="Đã chấm"),SUM('Làm nhanh'!L178),"") | G77: =IF(AND('Làm nhanh'!P178="Đã chấm"),SUM('Làm nhanh'!K178),"") | H77: =IF(AND('Làm nhanh'!P178="Đã chấm"),SUM('Làm nhanh'!N178),"") | I77: =IF(COUNT(F77:G77)<2,"",IF(OR(G77<=0,F77<0,F77>G77),"Lỗi nhập",F77/G77)) | L77: =IF(NOT(OR(COUNT(F77:H77)>0,LEN(F77&G77&H77)>0)),"",IF(NOT(ISNUMBER(I77)),"Lỗi/thiếu số đúng-tổng",IF(OR(MOD(F77,1)<>0,MOD(G77,1)<>0),"Lỗi/thiếu số đúng-tổng",IF(OR(AND(B77<>"N4",B77<>"N3",B77<>"N2"),AND(C77<>"Từ và kanji",C77<>"Ngữ pháp",C77<>"Đọc",C77<>"Nghe")),"Sai cấp/kỹ năng",IF(OR(NOT(ISNUMBER(A77)),A77<1),"Thiếu ngày đo",IF(D77="","Thiếu mã bài",IF(AND(E77<>"Mới",E77<>"Ôn lại"),"Thiếu loại câu",IF(OR(NOT(ISNUMBER(H77)),H77<=0),"Thiếu phút",IF(AND(E77="Mới",COUNTIFS($B$8:$B$79,B77,$C$8:$C$79,C77,$D$8:$D$79,D77,$E$8:$E$79,"Mới",$G$8:$G$79,">0")>1),"Trùng câu mới","Hợp lệ")))))))))
A78: =IF(AND('Làm nhanh'!P180="Đã chấm"),MAX('Làm nhanh'!M180),"") | B78: N3 | C78: Đọc | D78: START18-N3-R | E78: =IF(AND('Làm nhanh'!P180="Đã chấm"),IF(AND('Làm nhanh'!O180="Mới"),"Mới","Ôn lại"),"") | F78: =IF(AND('Làm nhanh'!P180="Đã chấm"),SUM('Làm nhanh'!L180),"") | G78: =IF(AND('Làm nhanh'!P180="Đã chấm"),SUM('Làm nhanh'!K180),"") | H78: =IF(AND('Làm nhanh'!P180="Đã chấm"),SUM('Làm nhanh'!N180),"") | I78: =IF(COUNT(F78:G78)<2,"",IF(OR(G78<=0,F78<0,F78>G78),"Lỗi nhập",F78/G78)) | L78: =IF(NOT(OR(COUNT(F78:H78)>0,LEN(F78&G78&H78)>0)),"",IF(NOT(ISNUMBER(I78)),"Lỗi/thiếu số đúng-tổng",IF(OR(MOD(F78,1)<>0,MOD(G78,1)<>0),"Lỗi/thiếu số đúng-tổng",IF(OR(AND(B78<>"N4",B78<>"N3",B78<>"N2"),AND(C78<>"Từ và kanji",C78<>"Ngữ pháp",C78<>"Đọc",C78<>"Nghe")),"Sai cấp/kỹ năng",IF(OR(NOT(ISNUMBER(A78)),A78<1),"Thiếu ngày đo",IF(D78="","Thiếu mã bài",IF(AND(E78<>"Mới",E78<>"Ôn lại"),"Thiếu loại câu",IF(OR(NOT(ISNUMBER(H78)),H78<=0),"Thiếu phút",IF(AND(E78="Mới",COUNTIFS($B$8:$B$79,B78,$C$8:$C$79,C78,$D$8:$D$79,D78,$E$8:$E$79,"Mới",$G$8:$G$79,">0")>1),"Trùng câu mới","Hợp lệ")))))))))
A79: =IF(AND('Làm nhanh'!P181="Đã chấm",'Làm nhanh'!P182="Đã chấm"),MAX('Làm nhanh'!M181,'Làm nhanh'!M182),"") | B79: N3 | C79: Nghe | D79: START18-N3-L | E79: =IF(AND('Làm nhanh'!P181="Đã chấm",'Làm nhanh'!P182="Đã chấm"),IF(AND('Làm nhanh'!O181="Mới",'Làm nhanh'!O182="Mới"),"Mới","Ôn lại"),"") | F79: =IF(AND('Làm nhanh'!P181="Đã chấm",'Làm nhanh'!P182="Đã chấm"),SUM('Làm nhanh'!L181,'Làm nhanh'!L182),"") | G79: =IF(AND('Làm nhanh'!P181="Đã chấm",'Làm nhanh'!P182="Đã chấm"),SUM('Làm nhanh'!K181,'Làm nhanh'!K182),"") | H79: =IF(AND('Làm nhanh'!P181="Đã chấm",'Làm nhanh'!P182="Đã chấm"),SUM('Làm nhanh'!N181,'Làm nhanh'!N182),"") | I79: =IF(COUNT(F79:G79)<2,"",IF(OR(G79<=0,F79<0,F79>G79),"Lỗi nhập",F79/G79)) | L79: =IF(NOT(OR(COUNT(F79:H79)>0,LEN(F79&G79&H79)>0)),"",IF(NOT(ISNUMBER(I79)),"Lỗi/thiếu số đúng-tổng",IF(OR(MOD(F79,1)<>0,MOD(G79,1)<>0),"Lỗi/thiếu số đúng-tổng",IF(OR(AND(B79<>"N4",B79<>"N3",B79<>"N2"),AND(C79<>"Từ và kanji",C79<>"Ngữ pháp",C79<>"Đọc",C79<>"Nghe")),"Sai cấp/kỹ năng",IF(OR(NOT(ISNUMBER(A79)),A79<1),"Thiếu ngày đo",IF(D79="","Thiếu mã bài",IF(AND(E79<>"Mới",E79<>"Ôn lại"),"Thiếu loại câu",IF(OR(NOT(ISNUMBER(H79)),H79<=0),"Thiếu phút",IF(AND(E79="Mới",COUNTIFS($B$8:$B$79,B79,$C$8:$C$79,C79,$D$8:$D$79,D79,$E$8:$E$79,"Mới",$G$8:$G$79,">0")>1),"Trùng câu mới","Hợp lệ")))))))))

Sheet Tổng hợp tuần
A2: Tổng hợp học tiếng Nhật trong tuần
A4: Tuần từ | B4: 46310 | C4: đến | D4: =B4+6 -> 46316 | E4: Đổi ngày ở B4 khi cần.
A6: Chỉ số | B6: Kết quả | C6: Cỡ mẫu | E6: Mã lỗi | F6: Bản ghi | G6: Ý nghĩa
A7: Phút học | B7: =IF(C7=0,"",SUMIFS('Nhật ký'!$E$8:$E$59,'Nhật ký'!$A$8:$A$59,">="&$B$4,'Nhật ký'!$A$8:$A$59,"<"&($B$4+7),'Nhật ký'!$O$8:$O$59,1)) | C7: =SUMIFS('Nhật ký'!$O$8:$O$59,'Nhật ký'!$A$8:$A$59,">="&$B$4,'Nhật ký'!$A$8:$A$59,"<"&($B$4+7)) -> 0 | E7: V | F7: =COUNTIFS('Nhật ký'!$A$8:$A$59,">="&$B$4,'Nhật ký'!$A$8:$A$59,"<"&($B$4+7),'Nhật ký'!$I$8:$I$59,E7)+COUNTIFS('Làm nhanh'!$M$172:$M$182,">="&$B$4,'Làm nhanh'!$M$172:$M$182,"<"&($B$4+7),'Làm nhanh'!$Q$172:$Q$182,E7,'Làm nhanh'!$P$172:$P$182,"Đã chấm") -> 0 | G7: Từ/kanji
A8: Phút nghe | B8: =IF(C8=0,"",SUMIFS('Nhật ký'!$F$8:$F$59,'Nhật ký'!$A$8:$A$59,">="&$B$4,'Nhật ký'!$A$8:$A$59,"<"&($B$4+7),'Nhật ký'!$M$8:$M$59,1)) | C8: =SUMIFS('Nhật ký'!$M$8:$M$59,'Nhật ký'!$A$8:$A$59,">="&$B$4,'Nhật ký'!$A$8:$A$59,"<"&($B$4+7)) -> 0 | E8: G | F8: =COUNTIFS('Nhật ký'!$A$8:$A$59,">="&$B$4,'Nhật ký'!$A$8:$A$59,"<"&($B$4+7),'Nhật ký'!$I$8:$I$59,E8)+COUNTIFS('Làm nhanh'!$M$172:$M$182,">="&$B$4,'Làm nhanh'!$M$172:$M$182,"<"&($B$4+7),'Làm nhanh'!$Q$172:$Q$182,E8,'Làm nhanh'!$P$172:$P$182,"Đã chấm") -> 0 | G8: Ngữ pháp
A9: Phút nói | B9: =IF(C9=0,"",SUMIFS('Nhật ký'!$G$8:$G$59,'Nhật ký'!$A$8:$A$59,">="&$B$4,'Nhật ký'!$A$8:$A$59,"<"&($B$4+7),'Nhật ký'!$N$8:$N$59,1)) | C9: =SUMIFS('Nhật ký'!$N$8:$N$59,'Nhật ký'!$A$8:$A$59,">="&$B$4,'Nhật ký'!$A$8:$A$59,"<"&($B$4+7)) -> 0 | E9: R | F9: =COUNTIFS('Nhật ký'!$A$8:$A$59,">="&$B$4,'Nhật ký'!$A$8:$A$59,"<"&($B$4+7),'Nhật ký'!$I$8:$I$59,E9)+COUNTIFS('Làm nhanh'!$M$172:$M$182,">="&$B$4,'Làm nhanh'!$M$172:$M$182,"<"&($B$4+7),'Làm nhanh'!$Q$172:$Q$182,E9,'Làm nhanh'!$P$172:$P$182,"Đã chấm") -> 0 | G9: Nối ý đọc
A10: Ngủ TB (giờ/24h) | B10: =IF(C10=0,"",SUMIFS('Nhật ký'!$B$8:$B$59,'Nhật ký'!$A$8:$A$59,">="&$B$4,'Nhật ký'!$A$8:$A$59,"<"&($B$4+7),'Nhật ký'!$K$8:$K$59,1)/C10) | C10: =SUMIFS('Nhật ký'!$K$8:$K$59,'Nhật ký'!$A$8:$A$59,">="&$B$4,'Nhật ký'!$A$8:$A$59,"<"&($B$4+7)) -> 0 | E10: A | F10: =COUNTIFS('Nhật ký'!$A$8:$A$59,">="&$B$4,'Nhật ký'!$A$8:$A$59,"<"&($B$4+7),'Nhật ký'!$I$8:$I$59,E10)+COUNTIFS('Làm nhanh'!$M$172:$M$182,">="&$B$4,'Làm nhanh'!$M$172:$M$182,"<"&($B$4+7),'Làm nhanh'!$Q$172:$Q$182,E10,'Làm nhanh'!$P$172:$P$182,"Đã chấm") -> 0 | G10: Nhận diện âm
A11: Mệt TB (1–5) | B11: =IF(C11=0,"",SUMIFS('Nhật ký'!$C$8:$C$59,'Nhật ký'!$A$8:$A$59,">="&$B$4,'Nhật ký'!$A$8:$A$59,"<"&($B$4+7),'Nhật ký'!$L$8:$L$59,1)/C11) | C11: =SUMIFS('Nhật ký'!$L$8:$L$59,'Nhật ký'!$A$8:$A$59,">="&$B$4,'Nhật ký'!$A$8:$A$59,"<"&($B$4+7)) -> 0 | E11: M | F11: =COUNTIFS('Nhật ký'!$A$8:$A$59,">="&$B$4,'Nhật ký'!$A$8:$A$59,"<"&($B$4+7),'Nhật ký'!$I$8:$I$59,E11)+COUNTIFS('Làm nhanh'!$M$172:$M$182,">="&$B$4,'Làm nhanh'!$M$172:$M$182,"<"&($B$4+7),'Làm nhanh'!$Q$172:$Q$182,E11,'Làm nhanh'!$P$172:$P$182,"Đã chấm") -> 0 | G11: Giữ thông tin
A12: Nhật ký cần sửa | B12: =SUM(COUNTIFS('Nhật ký'!$A$8:$A$59,">="&$B$4,'Nhật ký'!$A$8:$A$59,"<"&($B$4+7),'Nhật ký'!$J$8:$J$59,"Lỗi ngủ/mệt"),COUNTIFS('Nhật ký'!$A$8:$A$59,">="&$B$4,'Nhật ký'!$A$8:$A$59,"<"&($B$4+7),'Nhật ký'!$J$8:$J$59,"Thiếu tổng phút"),COUNTIFS('Nhật ký'!$A$8:$A$59,">="&$B$4,'Nhật ký'!$A$8:$A$59,"<"&($B$4+7),'Nhật ký'!$J$8:$J$59,"Lỗi phút"),COUNTIFS('Nhật ký'!$A$8:$A$59,">="&$B$4,'Nhật ký'!$A$8:$A$59,"<"&($B$4+7),'Nhật ký'!$J$8:$J$59,"Nghe+nói vượt tổng"),COUNTIFS('Nhật ký'!$A$8:$A$59,">="&$B$4,'Nhật ký'!$A$8:$A$59,"<"&($B$4+7),'Nhật ký'!$J$8:$J$59,"Thiếu chế độ"),COUNTIFS('Nhật ký'!$A$8:$A$59,">="&$B$4,'Nhật ký'!$A$8:$A$59,"<"&($B$4+7),'Nhật ký'!$J$8:$J$59,"Lỗi mã")) -> 0 | E12: T | F12: =COUNTIFS('Nhật ký'!$A$8:$A$59,">="&$B$4,'Nhật ký'!$A$8:$A$59,"<"&($B$4+7),'Nhật ký'!$I$8:$I$59,E12)+COUNTIFS('Làm nhanh'!$M$172:$M$182,">="&$B$4,'Làm nhanh'!$M$172:$M$182,"<"&($B$4+7),'Làm nhanh'!$Q$172:$Q$182,E12,'Làm nhanh'!$P$172:$P$182,"Đã chấm") -> 0 | G12: Thời gian
A13: Bản đo cần sửa | B13: =SUM(COUNTIF('Đo năng lực'!$L$8:$L$79,"Lỗi/thiếu số đúng-tổng"),COUNTIF('Đo năng lực'!$L$8:$L$79,"Sai cấp/kỹ năng"),COUNTIF('Đo năng lực'!$L$8:$L$79,"Thiếu ngày đo"),COUNTIF('Đo năng lực'!$L$8:$L$79,"Thiếu mã bài"),COUNTIF('Đo năng lực'!$L$8:$L$79,"Thiếu loại câu"),COUNTIF('Đo năng lực'!$L$8:$L$79,"Thiếu phút"),COUNTIF('Đo năng lực'!$L$8:$L$79,"Trùng câu mới")) -> 0 | C13: toàn sổ | E13: F | F13: =COUNTIFS('Nhật ký'!$A$8:$A$59,">="&$B$4,'Nhật ký'!$A$8:$A$59,"<"&($B$4+7),'Nhật ký'!$I$8:$I$59,E13)+COUNTIFS('Làm nhanh'!$M$172:$M$182,">="&$B$4,'Làm nhanh'!$M$172:$M$182,"<"&($B$4+7),'Làm nhanh'!$Q$172:$Q$182,E13,'Làm nhanh'!$P$172:$P$182,"Đã chấm") -> 0 | G13: Mệt/gián đoạn
A15: Câu Mới trong tuần, có ngày/phút/mã bài hợp lệ. Mỗi cấp và kỹ năng giữ riêng.
A17: Cấp | B17: Kỹ năng | C17: Đúng | D17: Tổng câu | E17: Độ đúng thô | F17: Phút làm | G17: Cỡ mẫu
A18: N4 | B18: Từ và kanji | C18: =IF(COUNTIFS('Đo năng lực'!$A$8:$A$79,">="&$B$4,'Đo năng lực'!$A$8:$A$79,"<"&($B$4+7),'Đo năng lực'!$B$8:$B$79,A18,'Đo năng lực'!$C$8:$C$79,B18,'Đo năng lực'!$E$8:$E$79,"Mới",'Đo năng lực'!$L$8:$L$79,"Hợp lệ")=0,"",SUMIFS('Đo năng lực'!$F$8:$F$79,'Đo năng lực'!$A$8:$A$79,">="&$B$4,'Đo năng lực'!$A$8:$A$79,"<"&($B$4+7),'Đo năng lực'!$B$8:$B$79,A18,'Đo năng lực'!$C$8:$C$79,B18,'Đo năng lực'!$E$8:$E$79,"Mới",'Đo năng lực'!$L$8:$L$79,"Hợp lệ")) | D18: =IF(COUNTIFS('Đo năng lực'!$A$8:$A$79,">="&$B$4,'Đo năng lực'!$A$8:$A$79,"<"&($B$4+7),'Đo năng lực'!$B$8:$B$79,A18,'Đo năng lực'!$C$8:$C$79,B18,'Đo năng lực'!$E$8:$E$79,"Mới",'Đo năng lực'!$L$8:$L$79,"Hợp lệ")=0,"",SUMIFS('Đo năng lực'!$G$8:$G$79,'Đo năng lực'!$A$8:$A$79,">="&$B$4,'Đo năng lực'!$A$8:$A$79,"<"&($B$4+7),'Đo năng lực'!$B$8:$B$79,A18,'Đo năng lực'!$C$8:$C$79,B18,'Đo năng lực'!$E$8:$E$79,"Mới",'Đo năng lực'!$L$8:$L$79,"Hợp lệ")) | E18: =IF(COUNT(C18:D18)<2,"",IF(D18>0,C18/D18,"")) | F18: =IF(COUNTIFS('Đo năng lực'!$A$8:$A$79,">="&$B$4,'Đo năng lực'!$A$8:$A$79,"<"&($B$4+7),'Đo năng lực'!$B$8:$B$79,A18,'Đo năng lực'!$C$8:$C$79,B18,'Đo năng lực'!$E$8:$E$79,"Mới",'Đo năng lực'!$L$8:$L$79,"Hợp lệ")=0,"",SUMIFS('Đo năng lực'!$H$8:$H$79,'Đo năng lực'!$A$8:$A$79,">="&$B$4,'Đo năng lực'!$A$8:$A$79,"<"&($B$4+7),'Đo năng lực'!$B$8:$B$79,A18,'Đo năng lực'!$C$8:$C$79,B18,'Đo năng lực'!$E$8:$E$79,"Mới",'Đo năng lực'!$L$8:$L$79,"Hợp lệ")) | G18: =IF(COUNT(D18)=0,"Chưa đo",IF(D18<10,"Mẫu nhỏ","Có "&D18&" câu")) -> Chưa đo
A19: N4 | B19: Ngữ pháp | C19: =IF(COUNTIFS('Đo năng lực'!$A$8:$A$79,">="&$B$4,'Đo năng lực'!$A$8:$A$79,"<"&($B$4+7),'Đo năng lực'!$B$8:$B$79,A19,'Đo năng lực'!$C$8:$C$79,B19,'Đo năng lực'!$E$8:$E$79,"Mới",'Đo năng lực'!$L$8:$L$79,"Hợp lệ")=0,"",SUMIFS('Đo năng lực'!$F$8:$F$79,'Đo năng lực'!$A$8:$A$79,">="&$B$4,'Đo năng lực'!$A$8:$A$79,"<"&($B$4+7),'Đo năng lực'!$B$8:$B$79,A19,'Đo năng lực'!$C$8:$C$79,B19,'Đo năng lực'!$E$8:$E$79,"Mới",'Đo năng lực'!$L$8:$L$79,"Hợp lệ")) | D19: =IF(COUNTIFS('Đo năng lực'!$A$8:$A$79,">="&$B$4,'Đo năng lực'!$A$8:$A$79,"<"&($B$4+7),'Đo năng lực'!$B$8:$B$79,A19,'Đo năng lực'!$C$8:$C$79,B19,'Đo năng lực'!$E$8:$E$79,"Mới",'Đo năng lực'!$L$8:$L$79,"Hợp lệ")=0,"",SUMIFS('Đo năng lực'!$G$8:$G$79,'Đo năng lực'!$A$8:$A$79,">="&$B$4,'Đo năng lực'!$A$8:$A$79,"<"&($B$4+7),'Đo năng lực'!$B$8:$B$79,A19,'Đo năng lực'!$C$8:$C$79,B19,'Đo năng lực'!$E$8:$E$79,"Mới",'Đo năng lực'!$L$8:$L$79,"Hợp lệ")) | E19: =IF(COUNT(C19:D19)<2,"",IF(D19>0,C19/D19,"")) | F19: =IF(COUNTIFS('Đo năng lực'!$A$8:$A$79,">="&$B$4,'Đo năng lực'!$A$8:$A$79,"<"&($B$4+7),'Đo năng lực'!$B$8:$B$79,A19,'Đo năng lực'!$C$8:$C$79,B19,'Đo năng lực'!$E$8:$E$79,"Mới",'Đo năng lực'!$L$8:$L$79,"Hợp lệ")=0,"",SUMIFS('Đo năng lực'!$H$8:$H$79,'Đo năng lực'!$A$8:$A$79,">="&$B$4,'Đo năng lực'!$A$8:$A$79,"<"&($B$4+7),'Đo năng lực'!$B$8:$B$79,A19,'Đo năng lực'!$C$8:$C$79,B19,'Đo năng lực'!$E$8:$E$79,"Mới",'Đo năng lực'!$L$8:$L$79,"Hợp lệ")) | G19: =IF(COUNT(D19)=0,"Chưa đo",IF(D19<10,"Mẫu nhỏ","Có "&D19&" câu")) -> Chưa đo
A20: N4 | B20: Đọc | C20: =IF(COUNTIFS('Đo năng lực'!$A$8:$A$79,">="&$B$4,'Đo năng lực'!$A$8:$A$79,"<"&($B$4+7),'Đo năng lực'!$B$8:$B$79,A20,'Đo năng lực'!$C$8:$C$79,B20,'Đo năng lực'!$E$8:$E$79,"Mới",'Đo năng lực'!$L$8:$L$79,"Hợp lệ")=0,"",SUMIFS('Đo năng lực'!$F$8:$F$79,'Đo năng lực'!$A$8:$A$79,">="&$B$4,'Đo năng lực'!$A$8:$A$79,"<"&($B$4+7),'Đo năng lực'!$B$8:$B$79,A20,'Đo năng lực'!$C$8:$C$79,B20,'Đo năng lực'!$E$8:$E$79,"Mới",'Đo năng lực'!$L$8:$L$79,"Hợp lệ")) | D20: =IF(COUNTIFS('Đo năng lực'!$A$8:$A$79,">="&$B$4,'Đo năng lực'!$A$8:$A$79,"<"&($B$4+7),'Đo năng lực'!$B$8:$B$79,A20,'Đo năng lực'!$C$8:$C$79,B20,'Đo năng lực'!$E$8:$E$79,"Mới",'Đo năng lực'!$L$8:$L$79,"Hợp lệ")=0,"",SUMIFS('Đo năng lực'!$G$8:$G$79,'Đo năng lực'!$A$8:$A$79,">="&$B$4,'Đo năng lực'!$A$8:$A$79,"<"&($B$4+7),'Đo năng lực'!$B$8:$B$79,A20,'Đo năng lực'!$C$8:$C$79,B20,'Đo năng lực'!$E$8:$E$79,"Mới",'Đo năng lực'!$L$8:$L$79,"Hợp lệ")) | E20: =IF(COUNT(C20:D20)<2,"",IF(D20>0,C20/D20,"")) | F20: =IF(COUNTIFS('Đo năng lực'!$A$8:$A$79,">="&$B$4,'Đo năng lực'!$A$8:$A$79,"<"&($B$4+7),'Đo năng lực'!$B$8:$B$79,A20,'Đo năng lực'!$C$8:$C$79,B20,'Đo năng lực'!$E$8:$E$79,"Mới",'Đo năng lực'!$L$8:$L$79,"Hợp lệ")=0,"",SUMIFS('Đo năng lực'!$H$8:$H$79,'Đo năng lực'!$A$8:$A$79,">="&$B$4,'Đo năng lực'!$A$8:$A$79,"<"&($B$4+7),'Đo năng lực'!$B$8:$B$79,A20,'Đo năng lực'!$C$8:$C$79,B20,'Đo năng lực'!$E$8:$E$79,"Mới",'Đo năng lực'!$L$8:$L$79,"Hợp lệ")) | G20: =IF(COUNT(D20)=0,"Chưa đo",IF(D20<10,"Mẫu nhỏ","Có "&D20&" câu")) -> Chưa đo
A21: N4 | B21: Nghe | C21: =IF(COUNTIFS('Đo năng lực'!$A$8:$A$79,">="&$B$4,'Đo năng lực'!$A$8:$A$79,"<"&($B$4+7),'Đo năng lực'!$B$8:$B$79,A21,'Đo năng lực'!$C$8:$C$79,B21,'Đo năng lực'!$E$8:$E$79,"Mới",'Đo năng lực'!$L$8:$L$79,"Hợp lệ")=0,"",SUMIFS('Đo năng lực'!$F$8:$F$79,'Đo năng lực'!$A$8:$A$79,">="&$B$4,'Đo năng lực'!$A$8:$A$79,"<"&($B$4+7),'Đo năng lực'!$B$8:$B$79,A21,'Đo năng lực'!$C$8:$C$79,B21,'Đo năng lực'!$E$8:$E$79,"Mới",'Đo năng lực'!$L$8:$L$79,"Hợp lệ")) | D21: =IF(COUNTIFS('Đo năng lực'!$A$8:$A$79,">="&$B$4,'Đo năng lực'!$A$8:$A$79,"<"&($B$4+7),'Đo năng lực'!$B$8:$B$79,A21,'Đo năng lực'!$C$8:$C$79,B21,'Đo năng lực'!$E$8:$E$79,"Mới",'Đo năng lực'!$L$8:$L$79,"Hợp lệ")=0,"",SUMIFS('Đo năng lực'!$G$8:$G$79,'Đo năng lực'!$A$8:$A$79,">="&$B$4,'Đo năng lực'!$A$8:$A$79,"<"&($B$4+7),'Đo năng lực'!$B$8:$B$79,A21,'Đo năng lực'!$C$8:$C$79,B21,'Đo năng lực'!$E$8:$E$79,"Mới",'Đo năng lực'!$L$8:$L$79,"Hợp lệ")) | E21: =IF(COUNT(C21:D21)<2,"",IF(D21>0,C21/D21,"")) | F21: =IF(COUNTIFS('Đo năng lực'!$A$8:$A$79,">="&$B$4,'Đo năng lực'!$A$8:$A$79,"<"&($B$4+7),'Đo năng lực'!$B$8:$B$79,A21,'Đo năng lực'!$C$8:$C$79,B21,'Đo năng lực'!$E$8:$E$79,"Mới",'Đo năng lực'!$L$8:$L$79,"Hợp lệ")=0,"",SUMIFS('Đo năng lực'!$H$8:$H$79,'Đo năng lực'!$A$8:$A$79,">="&$B$4,'Đo năng lực'!$A$8:$A$79,"<"&($B$4+7),'Đo năng lực'!$B$8:$B$79,A21,'Đo năng lực'!$C$8:$C$79,B21,'Đo năng lực'!$E$8:$E$79,"Mới",'Đo năng lực'!$L$8:$L$79,"Hợp lệ")) | G21: =IF(COUNT(D21)=0,"Chưa đo",IF(D21<10,"Mẫu nhỏ","Có "&D21&" câu")) -> Chưa đo
A22: N3 | B22: Từ và kanji | C22: =IF(COUNTIFS('Đo năng lực'!$A$8:$A$79,">="&$B$4,'Đo năng lực'!$A$8:$A$79,"<"&($B$4+7),'Đo năng lực'!$B$8:$B$79,A22,'Đo năng lực'!$C$8:$C$79,B22,'Đo năng lực'!$E$8:$E$79,"Mới",'Đo năng lực'!$L$8:$L$79,"Hợp lệ")=0,"",SUMIFS('Đo năng lực'!$F$8:$F$79,'Đo năng lực'!$A$8:$A$79,">="&$B$4,'Đo năng lực'!$A$8:$A$79,"<"&($B$4+7),'Đo năng lực'!$B$8:$B$79,A22,'Đo năng lực'!$C$8:$C$79,B22,'Đo năng lực'!$E$8:$E$79,"Mới",'Đo năng lực'!$L$8:$L$79,"Hợp lệ")) | D22: =IF(COUNTIFS('Đo năng lực'!$A$8:$A$79,">="&$B$4,'Đo năng lực'!$A$8:$A$79,"<"&($B$4+7),'Đo năng lực'!$B$8:$B$79,A22,'Đo năng lực'!$C$8:$C$79,B22,'Đo năng lực'!$E$8:$E$79,"Mới",'Đo năng lực'!$L$8:$L$79,"Hợp lệ")=0,"",SUMIFS('Đo năng lực'!$G$8:$G$79,'Đo năng lực'!$A$8:$A$79,">="&$B$4,'Đo năng lực'!$A$8:$A$79,"<"&($B$4+7),'Đo năng lực'!$B$8:$B$79,A22,'Đo năng lực'!$C$8:$C$79,B22,'Đo năng lực'!$E$8:$E$79,"Mới",'Đo năng lực'!$L$8:$L$79,"Hợp lệ")) | E22: =IF(COUNT(C22:D22)<2,"",IF(D22>0,C22/D22,"")) | F22: =IF(COUNTIFS('Đo năng lực'!$A$8:$A$79,">="&$B$4,'Đo năng lực'!$A$8:$A$79,"<"&($B$4+7),'Đo năng lực'!$B$8:$B$79,A22,'Đo năng lực'!$C$8:$C$79,B22,'Đo năng lực'!$E$8:$E$79,"Mới",'Đo năng lực'!$L$8:$L$79,"Hợp lệ")=0,"",SUMIFS('Đo năng lực'!$H$8:$H$79,'Đo năng lực'!$A$8:$A$79,">="&$B$4,'Đo năng lực'!$A$8:$A$79,"<"&($B$4+7),'Đo năng lực'!$B$8:$B$79,A22,'Đo năng lực'!$C$8:$C$79,B22,'Đo năng lực'!$E$8:$E$79,"Mới",'Đo năng lực'!$L$8:$L$79,"Hợp lệ")) | G22: =IF(COUNT(D22)=0,"Chưa đo",IF(D22<10,"Mẫu nhỏ","Có "&D22&" câu")) -> Chưa đo
A23: N3 | B23: Ngữ pháp | C23: =IF(COUNTIFS('Đo năng lực'!$A$8:$A$79,">="&$B$4,'Đo năng lực'!$A$8:$A$79,"<"&($B$4+7),'Đo năng lực'!$B$8:$B$79,A23,'Đo năng lực'!$C$8:$C$79,B23,'Đo năng lực'!$E$8:$E$79,"Mới",'Đo năng lực'!$L$8:$L$79,"Hợp lệ")=0,"",SUMIFS('Đo năng lực'!$F$8:$F$79,'Đo năng lực'!$A$8:$A$79,">="&$B$4,'Đo năng lực'!$A$8:$A$79,"<"&($B$4+7),'Đo năng lực'!$B$8:$B$79,A23,'Đo năng lực'!$C$8:$C$79,B23,'Đo năng lực'!$E$8:$E$79,"Mới",'Đo năng lực'!$L$8:$L$79,"Hợp lệ")) | D23: =IF(COUNTIFS('Đo năng lực'!$A$8:$A$79,">="&$B$4,'Đo năng lực'!$A$8:$A$79,"<"&($B$4+7),'Đo năng lực'!$B$8:$B$79,A23,'Đo năng lực'!$C$8:$C$79,B23,'Đo năng lực'!$E$8:$E$79,"Mới",'Đo năng lực'!$L$8:$L$79,"Hợp lệ")=0,"",SUMIFS('Đo năng lực'!$G$8:$G$79,'Đo năng lực'!$A$8:$A$79,">="&$B$4,'Đo năng lực'!$A$8:$A$79,"<"&($B$4+7),'Đo năng lực'!$B$8:$B$79,A23,'Đo năng lực'!$C$8:$C$79,B23,'Đo năng lực'!$E$8:$E$79,"Mới",'Đo năng lực'!$L$8:$L$79,"Hợp lệ")) | E23: =IF(COUNT(C23:D23)<2,"",IF(D23>0,C23/D23,"")) | F23: =IF(COUNTIFS('Đo năng lực'!$A$8:$A$79,">="&$B$4,'Đo năng lực'!$A$8:$A$79,"<"&($B$4+7),'Đo năng lực'!$B$8:$B$79,A23,'Đo năng lực'!$C$8:$C$79,B23,'Đo năng lực'!$E$8:$E$79,"Mới",'Đo năng lực'!$L$8:$L$79,"Hợp lệ")=0,"",SUMIFS('Đo năng lực'!$H$8:$H$79,'Đo năng lực'!$A$8:$A$79,">="&$B$4,'Đo năng lực'!$A$8:$A$79,"<"&($B$4+7),'Đo năng lực'!$B$8:$B$79,A23,'Đo năng lực'!$C$8:$C$79,B23,'Đo năng lực'!$E$8:$E$79,"Mới",'Đo năng lực'!$L$8:$L$79,"Hợp lệ")) | G23: =IF(COUNT(D23)=0,"Chưa đo",IF(D23<10,"Mẫu nhỏ","Có "&D23&" câu")) -> Chưa đo
A24: N3 | B24: Đọc | C24: =IF(COUNTIFS('Đo năng lực'!$A$8:$A$79,">="&$B$4,'Đo năng lực'!$A$8:$A$79,"<"&($B$4+7),'Đo năng lực'!$B$8:$B$79,A24,'Đo năng lực'!$C$8:$C$79,B24,'Đo năng lực'!$E$8:$E$79,"Mới",'Đo năng lực'!$L$8:$L$79,"Hợp lệ")=0,"",SUMIFS('Đo năng lực'!$F$8:$F$79,'Đo năng lực'!$A$8:$A$79,">="&$B$4,'Đo năng lực'!$A$8:$A$79,"<"&($B$4+7),'Đo năng lực'!$B$8:$B$79,A24,'Đo năng lực'!$C$8:$C$79,B24,'Đo năng lực'!$E$8:$E$79,"Mới",'Đo năng lực'!$L$8:$L$79,"Hợp lệ")) | D24: =IF(COUNTIFS('Đo năng lực'!$A$8:$A$79,">="&$B$4,'Đo năng lực'!$A$8:$A$79,"<"&($B$4+7),'Đo năng lực'!$B$8:$B$79,A24,'Đo năng lực'!$C$8:$C$79,B24,'Đo năng lực'!$E$8:$E$79,"Mới",'Đo năng lực'!$L$8:$L$79,"Hợp lệ")=0,"",SUMIFS('Đo năng lực'!$G$8:$G$79,'Đo năng lực'!$A$8:$A$79,">="&$B$4,'Đo năng lực'!$A$8:$A$79,"<"&($B$4+7),'Đo năng lực'!$B$8:$B$79,A24,'Đo năng lực'!$C$8:$C$79,B24,'Đo năng lực'!$E$8:$E$79,"Mới",'Đo năng lực'!$L$8:$L$79,"Hợp lệ")) | E24: =IF(COUNT(C24:D24)<2,"",IF(D24>0,C24/D24,"")) | F24: =IF(COUNTIFS('Đo năng lực'!$A$8:$A$79,">="&$B$4,'Đo năng lực'!$A$8:$A$79,"<"&($B$4+7),'Đo năng lực'!$B$8:$B$79,A24,'Đo năng lực'!$C$8:$C$79,B24,'Đo năng lực'!$E$8:$E$79,"Mới",'Đo năng lực'!$L$8:$L$79,"Hợp lệ")=0,"",SUMIFS('Đo năng lực'!$H$8:$H$79,'Đo năng lực'!$A$8:$A$79,">="&$B$4,'Đo năng lực'!$A$8:$A$79,"<"&($B$4+7),'Đo năng lực'!$B$8:$B$79,A24,'Đo năng lực'!$C$8:$C$79,B24,'Đo năng lực'!$E$8:$E$79,"Mới",'Đo năng lực'!$L$8:$L$79,"Hợp lệ")) | G24: =IF(COUNT(D24)=0,"Chưa đo",IF(D24<10,"Mẫu nhỏ","Có "&D24&" câu")) -> Chưa đo
A25: N3 | B25: Nghe | C25: =IF(COUNTIFS('Đo năng lực'!$A$8:$A$79,">="&$B$4,'Đo năng lực'!$A$8:$A$79,"<"&($B$4+7),'Đo năng lực'!$B$8:$B$79,A25,'Đo năng lực'!$C$8:$C$79,B25,'Đo năng lực'!$E$8:$E$79,"Mới",'Đo năng lực'!$L$8:$L$79,"Hợp lệ")=0,"",SUMIFS('Đo năng lực'!$F$8:$F$79,'Đo năng lực'!$A$8:$A$79,">="&$B$4,'Đo năng lực'!$A$8:$A$79,"<"&($B$4+7),'Đo năng lực'!$B$8:$B$79,A25,'Đo năng lực'!$C$8:$C$79,B25,'Đo năng lực'!$E$8:$E$79,"Mới",'Đo năng lực'!$L$8:$L$79,"Hợp lệ")) | D25: =IF(COUNTIFS('Đo năng lực'!$A$8:$A$79,">="&$B$4,'Đo năng lực'!$A$8:$A$79,"<"&($B$4+7),'Đo năng lực'!$B$8:$B$79,A25,'Đo năng lực'!$C$8:$C$79,B25,'Đo năng lực'!$E$8:$E$79,"Mới",'Đo năng lực'!$L$8:$L$79,"Hợp lệ")=0,"",SUMIFS('Đo năng lực'!$G$8:$G$79,'Đo năng lực'!$A$8:$A$79,">="&$B$4,'Đo năng lực'!$A$8:$A$79,"<"&($B$4+7),'Đo năng lực'!$B$8:$B$79,A25,'Đo năng lực'!$C$8:$C$79,B25,'Đo năng lực'!$E$8:$E$79,"Mới",'Đo năng lực'!$L$8:$L$79,"Hợp lệ")) | E25: =IF(COUNT(C25:D25)<2,"",IF(D25>0,C25/D25,"")) | F25: =IF(COUNTIFS('Đo năng lực'!$A$8:$A$79,">="&$B$4,'Đo năng lực'!$A$8:$A$79,"<"&($B$4+7),'Đo năng lực'!$B$8:$B$79,A25,'Đo năng lực'!$C$8:$C$79,B25,'Đo năng lực'!$E$8:$E$79,"Mới",'Đo năng lực'!$L$8:$L$79,"Hợp lệ")=0,"",SUMIFS('Đo năng lực'!$H$8:$H$79,'Đo năng lực'!$A$8:$A$79,">="&$B$4,'Đo năng lực'!$A$8:$A$79,"<"&($B$4+7),'Đo năng lực'!$B$8:$B$79,A25,'Đo năng lực'!$C$8:$C$79,B25,'Đo năng lực'!$E$8:$E$79,"Mới",'Đo năng lực'!$L$8:$L$79,"Hợp lệ")) | G25: =IF(COUNT(D25)=0,"Chưa đo",IF(D25<10,"Mẫu nhỏ","Có "&D25&" câu")) -> Chưa đo
A26: N2 | B26: Từ và kanji | C26: =IF(COUNTIFS('Đo năng lực'!$A$8:$A$79,">="&$B$4,'Đo năng lực'!$A$8:$A$79,"<"&($B$4+7),'Đo năng lực'!$B$8:$B$79,A26,'Đo năng lực'!$C$8:$C$79,B26,'Đo năng lực'!$E$8:$E$79,"Mới",'Đo năng lực'!$L$8:$L$79,"Hợp lệ")=0,"",SUMIFS('Đo năng lực'!$F$8:$F$79,'Đo năng lực'!$A$8:$A$79,">="&$B$4,'Đo năng lực'!$A$8:$A$79,"<"&($B$4+7),'Đo năng lực'!$B$8:$B$79,A26,'Đo năng lực'!$C$8:$C$79,B26,'Đo năng lực'!$E$8:$E$79,"Mới",'Đo năng lực'!$L$8:$L$79,"Hợp lệ")) | D26: =IF(COUNTIFS('Đo năng lực'!$A$8:$A$79,">="&$B$4,'Đo năng lực'!$A$8:$A$79,"<"&($B$4+7),'Đo năng lực'!$B$8:$B$79,A26,'Đo năng lực'!$C$8:$C$79,B26,'Đo năng lực'!$E$8:$E$79,"Mới",'Đo năng lực'!$L$8:$L$79,"Hợp lệ")=0,"",SUMIFS('Đo năng lực'!$G$8:$G$79,'Đo năng lực'!$A$8:$A$79,">="&$B$4,'Đo năng lực'!$A$8:$A$79,"<"&($B$4+7),'Đo năng lực'!$B$8:$B$79,A26,'Đo năng lực'!$C$8:$C$79,B26,'Đo năng lực'!$E$8:$E$79,"Mới",'Đo năng lực'!$L$8:$L$79,"Hợp lệ")) | E26: =IF(COUNT(C26:D26)<2,"",IF(D26>0,C26/D26,"")) | F26: =IF(COUNTIFS('Đo năng lực'!$A$8:$A$79,">="&$B$4,'Đo năng lực'!$A$8:$A$79,"<"&($B$4+7),'Đo năng lực'!$B$8:$B$79,A26,'Đo năng lực'!$C$8:$C$79,B26,'Đo năng lực'!$E$8:$E$79,"Mới",'Đo năng lực'!$L$8:$L$79,"Hợp lệ")=0,"",SUMIFS('Đo năng lực'!$H$8:$H$79,'Đo năng lực'!$A$8:$A$79,">="&$B$4,'Đo năng lực'!$A$8:$A$79,"<"&($B$4+7),'Đo năng lực'!$B$8:$B$79,A26,'Đo năng lực'!$C$8:$C$79,B26,'Đo năng lực'!$E$8:$E$79,"Mới",'Đo năng lực'!$L$8:$L$79,"Hợp lệ")) | G26: =IF(COUNT(D26)=0,"Chưa đo",IF(D26<10,"Mẫu nhỏ","Có "&D26&" câu")) -> Chưa đo
A27: N2 | B27: Ngữ pháp | C27: =IF(COUNTIFS('Đo năng lực'!$A$8:$A$79,">="&$B$4,'Đo năng lực'!$A$8:$A$79,"<"&($B$4+7),'Đo năng lực'!$B$8:$B$79,A27,'Đo năng lực'!$C$8:$C$79,B27,'Đo năng lực'!$E$8:$E$79,"Mới",'Đo năng lực'!$L$8:$L$79,"Hợp lệ")=0,"",SUMIFS('Đo năng lực'!$F$8:$F$79,'Đo năng lực'!$A$8:$A$79,">="&$B$4,'Đo năng lực'!$A$8:$A$79,"<"&($B$4+7),'Đo năng lực'!$B$8:$B$79,A27,'Đo năng lực'!$C$8:$C$79,B27,'Đo năng lực'!$E$8:$E$79,"Mới",'Đo năng lực'!$L$8:$L$79,"Hợp lệ")) | D27: =IF(COUNTIFS('Đo năng lực'!$A$8:$A$79,">="&$B$4,'Đo năng lực'!$A$8:$A$79,"<"&($B$4+7),'Đo năng lực'!$B$8:$B$79,A27,'Đo năng lực'!$C$8:$C$79,B27,'Đo năng lực'!$E$8:$E$79,"Mới",'Đo năng lực'!$L$8:$L$79,"Hợp lệ")=0,"",SUMIFS('Đo năng lực'!$G$8:$G$79,'Đo năng lực'!$A$8:$A$79,">="&$B$4,'Đo năng lực'!$A$8:$A$79,"<"&($B$4+7),'Đo năng lực'!$B$8:$B$79,A27,'Đo năng lực'!$C$8:$C$79,B27,'Đo năng lực'!$E$8:$E$79,"Mới",'Đo năng lực'!$L$8:$L$79,"Hợp lệ")) | E27: =IF(COUNT(C27:D27)<2,"",IF(D27>0,C27/D27,"")) | F27: =IF(COUNTIFS('Đo năng lực'!$A$8:$A$79,">="&$B$4,'Đo năng lực'!$A$8:$A$79,"<"&($B$4+7),'Đo năng lực'!$B$8:$B$79,A27,'Đo năng lực'!$C$8:$C$79,B27,'Đo năng lực'!$E$8:$E$79,"Mới",'Đo năng lực'!$L$8:$L$79,"Hợp lệ")=0,"",SUMIFS('Đo năng lực'!$H$8:$H$79,'Đo năng lực'!$A$8:$A$79,">="&$B$4,'Đo năng lực'!$A$8:$A$79,"<"&($B$4+7),'Đo năng lực'!$B$8:$B$79,A27,'Đo năng lực'!$C$8:$C$79,B27,'Đo năng lực'!$E$8:$E$79,"Mới",'Đo năng lực'!$L$8:$L$79,"Hợp lệ")) | G27: =IF(COUNT(D27)=0,"Chưa đo",IF(D27<10,"Mẫu nhỏ","Có "&D27&" câu")) -> Chưa đo
